Workbook

Sheet PQ
A1: PDV | B1: CORE | C1: LATONES | D1: VALUE LITRO | E1: Corona 710cc | F1: VALUE LATA | G1: SIN ALCOHOL | H1: PREMIUM | I1: MICHELOB | J1: CORONA PORRON | K1: VALUE LATON | L1: CORE 2
A2: 6 | B2: 0b 1% | 2b 5% | 4b 6% | C2: 1b 4% | 5b 7% | 97b 0% | E2: 1b 10% | 85b 0% | G2: 0b 0% | H2: 0b 0% | 2b 2% | 5b 3,5% | 10b 5% | I2: 1b 7% | 3b 22% | 8b 27% | J2: 1b 5% | 20b 0%
A3: 15 | B3: 0b 1% | 2b 5% | 4b 6% | C3: 1b 4% | 5b 7% | 97b 0% | E3: 1b 10% | 85b 0% | G3: 0b 0% | H3: 0b 0% | 2b 2% | 5b 3,5% | 10b 5% | I3: 1b 7% | 3b 22% | 8b 27% | J3: 1b 5% | 20b 0%
A4: 27 | B4: 0b 1% | 3b 4% | 5b 6% | C4: 2b 3% | 4b 5% | 5b 8% | 193 0% | D4: 1b 12% | E4: 1b 10% | 85b 0% | F4: 1b 15% | 100b 18% | G4: 0b 0% | H4: 0b 0% | 2b 2% | 5b 3,5% | 10b 5% | I4: 1b 7% | 3b 22% | 8b 27% | J4: 1b 5% | 20b 0% | K4: 1b 10% | 5b 15% | 192b 0%
A5: 33 | B5: 0b 1% | 2b 5% | 4b 6% | C5: 1b 4% | 5b 7% | 97b 0%
A6: 39 | E6: 1b 10% | 85b 0% | G6: 0b 0% | H6: 0b 0% | 2b 2% | 5b 3,5% | 10b 5% | I6: 1b 7% | 3b 22% | 8b 27% | J6: 1b 5% | 20b 0%
A7: 45 | B7: 0b 1% | 6b 5% | 10b 6% | C7: 2b 3% | 4b 5% | 5b 8% | 193 0% | D7: 1b 12% | E7: 1b 10% | 85b 0% | F7: 1b 15% | 100b 18% | G7: 0b 0% | H7: 0b 0% | 2b 2% | 5b 3,5% | 10b 5% | I7: 1b 7% | 3b 22% | 8b 27% | J7: 1b 5% | 20b 0% | K7: 1b 10% | 5b 15% | 192b 0% | L7: 25b 9%
A8: 55 | B8: 0b 1% | 3b 4% | 5b 6% | C8: 2b 3% | 4b 5% | 5b 8% | 193 0% | D8: 1b 12% | E8: 1b 10% | 85b 0% | F8: 1b 15% | 100b 18% | G8: 0b 0% | H8: 0b 0% | 2b 2% | 5b 3,5% | 10b 5% | I8: 1b 7% | 3b 22% | 8b 27% | J8: 1b 5% | 20b 0% | K8: 1b 10% | 5b 15% | 192b 0%
A9: 63 | B9: 0b 1% | 2b 5% | 4b 6% | C9: 1b 4% | 5b 7% | 97b 0% | D9: 1b 12% | E9: 1b 10% | 85b 0% | F9: 1b 15% | 100b 18% | G9: 0b 0% | H9: 0b 0% | 2b 2% | 5b 3,5% | 10b 5% | I9: 1b 7% | 3b 22% | 8b 27% | J9: 1b 5% | 20b 0% | K9: 1b 10% | 5b 15% | 192b 0%
A10: 71 | B10: 0b 1% | 3b 4% | 5b 6% | C10: 1b 4% | 5b 7% | 97b 0% | D10: 1b 12% | E10: 1b 10% | 85b 0% | F10: 1b 15% | 100b 18% | G10: 0b 0% | H10: 0b 0% | 2b 2% | 5b 3,5% | 10b 5% | I10: 1b 7% | 3b 22% | 8b 27% | J10: 1b 5% | 20b 0% | K10: 1b 10% | 5b 15% | 192b 0%
A11: 72 | B11: 0b 1% | 2b 5% | 4b 6% | C11: 1b 4% | 5b 7% | 97b 0% | D11: 1b 12% | E11: 1b 10% | 85b 0% | F11: 1b 15% | 100b 18% | G11: 0b 0% | H11: 0b 0% | 2b 2% | 5b 3,5% | 10b 5% | I11: 1b 7% | 3b 22% | 8b 27% | J11: 1b 5% | 20b 0% | K11: 1b 10% | 5b 15% | 192b 0%
A12: 96 | B12: 0b 1% | 2b 5% | 4b 6% | C12: 1b 4% | 5b 7% | 97b 0%
A13: 132 | B13: 0b 1% | 3b 4% | 5b 6% | C13: 2b 3% | 4b 5% | 5b 8% | 193 0% | D13: 1b 12% | E13: 1b 10% | 85b 0% | F13: 1b 15% | 100b 18% | G13: 0b 0% | H13: 0b 0% | 2b 2% | 5b 3,5% | 10b 5% | I13: 1b 7% | 3b 22% | 8b 27% | J13: 1b 5% | 20b 0% | K13: 1b 10% | 5b 15% | 192b 0%
A14: 149 | B14: 0b 1% | 2b 5% | 4b 6% | C14: 1b 4% | 5b 7% | 97b 0% | D14: 1b 12% | E14: 1b 10% | 85b 0% | F14: 1b 15% | 100b 18% | G14: 0b 0% | H14: 0b 0% | 2b 2% | 5b 3,5% | 10b 5% | I14: 1b 7% | 3b 22% | 8b 27% | J14: 1b 5% | 20b 0% | K14: 1b 10% | 5b 15% | 192b 0%
A15: 170 | B15: 0b 1% | 2b 5% | 4b 6% | C15: 1b 4% | 5b 7% | 97b 0% | E15: 1b 10% | 85b 0% | G15: 0b 0% | H15: 0b 0% | 2b 2% | 5b 3,5% | 10b 5% | I15: 1b 7% | 3b 22% | 8b 27% | J15: 1b 5% | 20b 0%
A16: 197 | B16: 0b 1% | 6b 5% | 10b 6% | C16: 2b 3% | 4b 5% | 5b 8% | 193 0% | D16: 1b 12% | E16: 1b 10% | 85b 0% | F16: 1b 15% | 100b 18% | G16: 0b 0% | H16: 0b 0% | 2b 2% | 5b 3,5% | 10b 5% | I16: 1b 7% | 3b 22% | 8b 27% | J16: 1b 5% | 20b 0% | K16: 1b 10% | 5b 15% | 192b 0%
A17: 229 | B17: 0b 1% | 2b 5% | 4b 6% | C17: 1b 4% | 5b 7% | 97b 0% | D17: 1b 12% | E17: 1b 10% | 85b 0% | F17: 1b 15% | 100b 18% | G17: 0b 0% | H17: 0b 0% | 2b 2% | 5b 3,5% | 10b 5% | I17: 1b 7% | 3b 22% | 8b 27% | J17: 1b 5% | 20b 0% | K17: 1b 10% | 5b 15% | 192b 0%
A18: 246 | B18: 0b 1% | 5b 4% | 10b 5% | 15b 6% | 25b 9% | C18: 6b 4% | 12b 5% | 15b 8% | 385b 0% | D18: 3b 12% | E18: 3b 10% | 169b 0% | F18: 3b 15% | 100b 18% | G18: 0b 0% | H18: 0b 0% | 5b 2% | 10b 3,5% | 20b 5% | I18: 1b 7% | 3b 22% | 8b 27% | J18: 3b 5% | 42b 0% | K18: 3b 10% | 10b 15% | 384b 0%
A19: 247 | B19: 0b 1% | 3b 4% | 5b 6% | C19: 1b 4% | 5b 7% | 97b 0% | E19: 1b 10% | 85b 0% | G19: 0b 0% | H19: 0b 0% | 2b 2% | 5b 3,5% | 10b 5% | I19: 1b 7% | 3b 22% | 8b 27% | J19: 1b 5% | 20b 0%
A20: 255 | B20: 0b 1% | 6b 5% | 10b 6% | C20: 1b 4% | 5b 7% | 97b 0% | D20: 1b 12% | E20: 1b 10% | 85b 0% | F20: 1b 15% | 100b 18% | G20: 0b 0% | H20: 0b 0% | 2b 2% | 5b 3,5% | 10b 5% | I20: 1b 7% | 3b 22% | 8b 27% | J20: 1b 5% | 20b 0% | K20: 1b 10% | 5b 15% | 192b 0%
A21: 289 | B21: 0b 1% | 2b 5% | 4b 6% | C21: 1b 4% | 5b 7% | 97b 0% | D21: 1b 12% | E21: 1b 10% | 85b 0% | F21: 1b 15% | 100b 18% | G21: 0b 0% | H21: 0b 0% | 2b 2% | 5b 3,5% | 10b 5% | I21: 1b 7% | 3b 22% | 8b 27% | J21: 1b 5% | 20b 0% | K21: 1b 10% | 5b 15% | 192b 0%
A22: 294 | B22: 0b 1% | 2b 5% | 4b 6% | C22: 1b 4% | 5b 7% | 97b 0% | D22: 1b 12% | E22: 1b 10% | 85b 0% | F22: 1b 15% | 100b 18% | G22: 0b 0% | H22: 0b 0% | 2b 2% | 5b 3,5% | 10b 5% | I22: 1b 7% | 3b 22% | 8b 27% | J22: 1b 5% | 20b 0% | K22: 1b 10% | 5b 15% | 192b 0%
A23: 311 | B23: 0b 1% | 2b 5% | 4b 6% | C23: 2b 3% | 4b 5% | 5b 8% | 193 0% | E23: 1b 10% | 85b 0% | G23: 0b 0% | H23: 0b 0% | 2b 2% | 5b 3,5% | 10b 5% | I23: 1b 7% | 3b 22% | 8b 27% | J23: 1b 5% | 20b 0%
A24: 312 | B24: 0b 1% | 6b 5% | 10b 6% | C24: 2b 3% | 4b 4% | 6b 5% | 10b 8% | 385b 0% | D24: 3b 12% | E24: 1b 10% | 85b 0% | F24: 3b 15% | 100b 18% | G24: 0b 0% | H24: 0b 0% | 2b 2% | 5b 3,5% | 10b 5% | I24: 1b 7% | 3b 22% | 8b 27% | J24: 1b 5% | 20b 0% | K24: 1b 10% | 5b 15% | 192b 0% | L24: 25b 9%
A25: 322 | E25: 1b 10% | 85b 0% | G25: 0b 0% | H25: 0b 0% | 2b 2% | 5b 3,5% | 10b 5% | I25: 1b 7% | 3b 22% | 8b 27% | J25: 1b 5% | 20b 0%
A26: 327 | B26: 0b 1% | 2b 5% | 4b 6% | C26: 1b 4% | 5b 7% | 97b 0% | D26: 1b 12% | E26: 1b 10% | 85b 0% | F26: 1b 15% | 100b 18% | G26: 0b 0% | H26: 0b 0% | 2b 2% | 5b 3,5% | 10b 5% | I26: 1b 7% | 3b 22% | 8b 27% | J26: 1b 5% | 20b 0% | K26: 1b 10% | 5b 15% | 192b 0%
A27: 337 | B27: 0b 1% | 2b 5% | 4b 6% | C27: 1b 4% | 5b 7% | 97b 0% | D27: 1b 12% | E27: 1b 10% | 85b 0% | F27: 1b 15% | 100b 18% | G27: 0b 0% | H27: 0b 0% | 2b 2% | 5b 3,5% | 10b 5% | I27: 1b 7% | 3b 22% | 8b 27% | J27: 1b 5% | 20b 0% | K27: 1b 10% | 5b 15% | 192b 0%
A28: 352 | B28: 0b 1% | 2b 5% | 4b 6% | C28: 1b 4% | 5b 7% | 97b 0% | D28: 1b 12% | E28: 1b 10% | 85b 0% | F28: 1b 15% | 100b 18% | G28: 0b 0% | H28: 0b 0% | 2b 2% | 5b 3,5% | 10b 5% | I28: 1b 7% | 3b 22% | 8b 27% | J28: 1b 5% | 20b 0% | K28: 1b 10% | 5b 15% | 192b 0%
A29: 369 | B29: 0b 1% | 2b 5% | 4b 6% | C29: 1b 4% | 5b 7% | 97b 0% | G29: 0b 0% | H29: 0b 0% | 2b 2% | 5b 3,5% | 10b 5% | I29: 1b 7% | 3b 22% | 8b 27% | J29: 1b 5% | 20b 0%
A30: 381 | B30: 0b 1% | 2b 5% | 4b 6% | C30: 1b 4% | 5b 7% | 97b 0% | E30: 1b 10% | 85b 0% | G30: 0b 0% | H30: 0b 0% | 2b 2% | 5b 3,5% | 10b 5% | I30: 1b 7% | 3b 22% | 8b 27% | J30: 1b 5% | 20b 0%
A31: 392 | B31: 0b 1% | 2b 5% | 4b 6% | C31: 1b 4% | 5b 7% | 97b 0% | D31: 1b 12% | E31: 1b 10% | 85b 0% | F31: 1b 15% | 100b 18% | G31: 0b 0% | H31: 0b 0% | 2b 2% | 5b 3,5% | 10b 5% | I31: 1b 7% | 3b 22% | 8b 27% | J31: 1b 5% | 20b 0% | K31: 1b 10% | 5b 15% | 192b 0%
A32: 428 | B32: 0b 1% | 2b 5% | 4b 6% | C32: 1b 4% | 5b 7% | 97b 0% | D32: 1b 12% | E32: 1b 10% | 85b 0% | F32: 1b 15% | 100b 18% | G32: 0b 0% | H32: 0b 0% | 2b 2% | 5b 3,5% | 10b 5% | I32: 1b 7% | 3b 22% | 8b 27% | J32: 1b 5% | 20b 0% | K32: 1b 10% | 5b 15% | 192b 0%
A33: 437 | B33: 0b 1% | 15b 4% | 40b 5% | 60b 9% | C33: 2b 3% | 4b 4% | 6b 5% | 10b 8% | 385b 0% | D33: 1b 12% | E33: 3b 10% | 169b 0% | F33: 1b 15% | 100b 18% | G33: 0b 0% | H33: 0b 0% | 5b 2% | 10b 3,5% | 20b 5% | I33: 1b 7% | 3b 22% | 8b 27% | J33: 3b 5% | 42b 0% | K33: 1b 10% | 5b 15% | 192b 0%
A34: 441 | E34: 1b 10% | 85b 0% | G34: 0b 0% | H34: 0b 0% | 2b 2% | 5b 3,5% | 10b 5% | I34: 1b 7% | 3b 22% | 8b 27% | J34: 1b 5% | 20b 0%
A35: 462 | B35: 0b 1% | 2b 5% | 4b 6% | C35: 1b 4% | 5b 7% | 97b 0% | D35: 1b 12% | E35: 1b 10% | 85b 0% | F35: 1b 15% | 100b 18% | G35: 0b 0% | H35: 0b 0% | 2b 2% | 5b 3,5% | 10b 5% | I35: 1b 7% | 3b 22% | 8b 27% | J35: 1b 5% | 20b 0% | K35: 1b 10% | 5b 15% | 192b 0%
A36: 493 | B36: 0b 1% | 3b 4% | 5b 6% | C36: 2b 3% | 4b 5% | 5b 8% | 193 0% | D36: 1b 12% | E36: 1b 10% | 85b 0% | F36: 1b 15% | 100b 18% | G36: 0b 0% | H36: 0b 0% | 2b 2% | 5b 3,5% | 10b 5% | I36: 1b 7% | 3b 22% | 8b 27% | J36: 1b 5% | 20b 0% | K36: 1b 10% | 5b 15% | 192b 0%
A37: 501 | B37: 0b 1% | 2b 5% | 4b 6% | C37: 2b 3% | 4b 5% | 5b 8% | 193 0% | D37: 1b 12% | E37: 1b 10% | 85b 0% | F37: 1b 15% | 100b 18% | G37: 0b 0% | H37: 0b 0% | 2b 2% | 5b 3,5% | 10b 5% | I37: 1b 7% | 3b 22% | 8b 27% | J37: 1b 5% | 20b 0% | K37: 1b 10% | 5b 15% | 192b 0%
A38: 521 | B38: 0b 1% | 2b 5% | 4b 6% | C38: 1b 4% | 5b 7% | 97b 0% | E38: 1b 10% | 85b 0% | G38: 0b 0% | H38: 0b 0% | 2b 2% | 5b 3,5% | 10b 5% | I38: 1b 7% | 3b 22% | 8b 27% | J38: 1b 5% | 20b 0%
A39: 531 | E39: 1b 10% | 85b 0% | G39: 0b 0% | H39: 0b 0% | 2b 2% | 5b 3,5% | 10b 5% | I39: 1b 7% | 3b 22% | 8b 27% | J39: 1b 5% | 20b 0%
A40: 532 | B40: 0b 1% | 2b 5% | 4b 6% | C40: 1b 4% | 5b 7% | 97b 0% | D40: 1b 12% | E40: 1b 10% | 85b 0% | F40: 1b 15% | 100b 18% | G40: 0b 0% | H40: 0b 0% | 2b 2% | 5b 3,5% | 10b 5% | I40: 1b 7% | 3b 22% | 8b 27% | J40: 1b 5% | 20b 0% | K40: 1b 10% | 5b 15% | 192b 0%
...

Sheet Listados
A1: B2B | B1: Acción | C1: PDV | D1: Listado | E1: Detalle | G1: B2B | H1: Acción | I1: PDV | J1: Listado | K1: Detalle | M1: B2B | N1: Acción | O1: PDV | P1: Listado | Q1: Detalle | S1: B2B | T1: Acción | U1: PDV | V1: Listado | W1: Detalle | Y1: B2B | Z1: Acción | AA1: PDV | AB1: Listado | AC1: Detalle | AE1: B2B | AF1: Acción | AG1: PDV | AH1: Listado | AI1: Detalle | AK1: B2B | AL1: Acción | AM1: PDV | AN1: Listado | AO1: Detalle | AQ1: B2B | AR1: Acción | AS1: PDV | AT1: Listado | AU1: Detalle | AW1: B2B | AX1: Acción | AY1: PDV | AZ1: Listado | BA1: Detalle | BC1: B2B | BD1: Acción | BE1: PDV | BF1: Listado | BG1: Detalle | BI1: B2B | BJ1: Acción | BK1: PDV | BL1: Listado | BM1: Detalle | BO1: B2B | BP1: Acción | BQ1: PDV | BR1: Listado | BS1: Detalle | BU1: B2B | BV1: Acción | BW1: PDV | BX1: Listado | BY1: Detalle | CA1: B2B | CB1: Acción | CC1: PDV | CD1: Listado | CE1: Detalle | CG1: B2B | CH1: Acción | CI1: PDV | CJ1: Listado | CK1: Detalle | CM1: B2B | CN1: Acción | CO1: PDV | CP1: Listado | CQ1: Detalle | CS1: B2B | CT1: Acción | CU1: PDV | CV1: Listado | CW1: Detalle | CY1: B2B | CZ1: Acción | DA1: PDV | DB1: Listado | DC1: Detalle | DE1: B2B | DF1: Acción | DG1: PDV | DH1: Listado | DI1: Detalle | DK1: B2B | DL1: Acción | DM1: PDV | DN1: Listado | DO1: Detalle | DQ1: B2B | DR1: Acción | DS1: PDV | DT1: Listado | DU1: Detalle | DW1: B2B | DX1: Acción | DY1: PDV | DZ1: Listado | EA1: Detalle | EC1: B2B | ED1: Acción | EE1: PDV | EF1: Listado | EG1: Detalle | EI1: B2B | EJ1: Acción | EK1: PDV | EL1: Listado | EM1: Detalle | EO1: B2B | EP1: Acción | EQ1: PDV | ER1: Listado | ES1: Detalle | EU1: B2B | EV1: Acción | EW1: PDV | EX1: Listado | EY1: Detalle | EZ1: B2B | FA1: Acción | FB1: PDV | FC1: Listado | FD1: Detalle | FE1: B2B | FF1: Acción | FG1: PDV | FH1: Listado | FI1: Detalle | FJ1: B2B | FK1: Acción | FL1: PDV | FM1: Listado | FN1: Detalle | FO1: B2B | FP1: Acción | FQ1: PDV | FR1: Listado | FS1: Detalle | FT1: B2B | FU1: Acción | FV1: PDV | FW1: Listado | FX1: Detalle | FY1: B2B | FZ1: Acción | GA1: PDV | GB1: Listado | GC1: Detalle | GD1: B2B | GE1: Acción | GF1: PDV | GG1: Listado | GH1: Detalle
A2: 246 | B2: TIER 1 CORE AS | C2: =+IFERROR(VALUE(RIGHT(Tabla1[[#This Row],[B2B]],6)),"") -> 246 | D2: =+IFERROR(VLOOKUP(B2,Auxiliar!$A:$C,2,0),"") -> CORE | E2: =+IFERROR(VLOOKUP(B2,Auxiliar!$A:$C,3,0),"") -> 0b 1% | 5b 4% | 10b 5% | 15b 6% | 25b 9% | G2: 437 | H2: TIER 2 CORE AS | I2: =+IFERROR(VALUE(RIGHT(Tabla2[[#This Row],[B2B]],6)),"") -> 437 | J2: =+IFERROR(VLOOKUP(H2,Auxiliar!$A:$C,2,0),"") -> CORE | K2: =+IFERROR(VLOOKUP(H2,Auxiliar!$A:$C,3,0),"") -> 0b 1% | 15b 4% | 40b 5% | 60b 9% | M2: 3936 | N2: TIER 3 CORE AS | O2: =+IFERROR(VALUE(RIGHT(Tabla3[[#This Row],[B2B]],6)),"") -> 3936 | P2: =+IFERROR(VLOOKUP(N2,Auxiliar!$A:$C,2,0),"") -> CORE | Q2: =+IFERROR(VLOOKUP(N2,Auxiliar!$A:$C,3,0),"") -> 0b 1% | 60b 4% | 100b 8% | 150b 9% | S2: 6 | T2: TIER 1 CORE KT | U2: =+IFERROR(VALUE(RIGHT(Tabla4[[#This Row],[B2B]],6)),"") -> 6 | V2: =+IFERROR(VLOOKUP(T2,Auxiliar!$A:$C,2,0),"") -> CORE | W2: =+IFERROR(VLOOKUP(T2,Auxiliar!$A:$C,3,0),"") -> 0b 1% | 2b 5% | 4b 6% | Y2: 27 | Z2: TIER 2 CORE KT | AA2: =+IFERROR(VALUE(RIGHT(Tabla5[[#This Row],[B2B]],6)),"") -> 27 | AB2: =+IFERROR(VLOOKUP(Z2,Auxiliar!$A:$C,2,0),"") -> CORE | AC2: =+IFERROR(VLOOKUP(Z2,Auxiliar!$A:$C,3,0),"") -> 0b 1% | 3b 4% | 5b 6% | AE2: 45 | AF2: TIER 3 CORE KT | AG2: =+IFERROR(VALUE(RIGHT(Tabla6[[#This Row],[B2B]],6)),"") -> 45 | AH2: =+IFERROR(VLOOKUP(AF2,Auxiliar!$A:$C,2,0),"") -> CORE | AI2: =+IFERROR(VLOOKUP(AF2,Auxiliar!$A:$C,3,0),"") -> 0b 1% | 6b 5% | 10b 6% | AK2: 6 | AL2: LATONES KT 1 | AM2: =+IFERROR(VALUE(RIGHT(Tabla7[[#This Row],[B2B]],6)),"") -> 6 | AN2: =+IFERROR(VLOOKUP(AL2,Auxiliar!$A:$C,2,0),"") -> LATONES | AO2: =+IFERROR(VLOOKUP(AL2,Auxiliar!$A:$C,3,0),"") -> 1b 4% | 5b 7% | 97b 0% | AQ2: 27 | AR2: LATONES KT 2 | AS2: =+IFERROR(VALUE(RIGHT(Tabla8[[#This Row],[B2B]],6)),"") -> 27 | AT2: =+IFERROR(VLOOKUP(AR2,Auxiliar!$A:$C,2,0),"") -> LATONES | AU2: =+IFERROR(VLOOKUP(AR2,Auxiliar!$A:$C,3,0),"") -> 2b 3% | 4b 5% | 5b 8% | 193 0% | AW2: 312 | AX2: LATONES AS 1 | AY2: =+IFERROR(VALUE(RIGHT(Tabla9[[#This Row],[B2B]],6)),"") -> 312 | AZ2: =+IFERROR(VLOOKUP(AX2,Auxiliar!$A:$C,2,0),"") -> LATONES | BA2: =+IFERROR(VLOOKUP(AX2,Auxiliar!$A:$C,3,0),"") -> 2b 3% | 4b 4% | 6b 5% | 10b 8% | 385b 0% | BC2: 246 | BD2: LATONES AS 2 | BE2: =+IFERROR(VALUE(RIGHT(Tabla10[[#This Row],[B2B]],6)),"") -> 246 | BF2: =+IFERROR(VLOOKUP(BD2,Auxiliar!$A:$C,2,0),"") -> LATONES | BG2: =+IFERROR(VLOOKUP(BD2,Auxiliar!$A:$C,3,0),"") -> 6b 4% | 12b 5% | 15b 8% | 385b 0% | BI2: 3897 | BJ2: 1890 LITRO AS | BK2: =+IFERROR(VALUE(RIGHT(Tabla11[[#This Row],[B2B]],6)),"") -> 3897 | BL2: =+IFERROR(VLOOKUP(BJ2,Auxiliar!$A:$C,2,0),"") -> VALUE LITRO | BM2: =+IFERROR(VLOOKUP(BJ2,Auxiliar!$A:$C,3,0),"") -> 3b 12% | BO2: 5508 | BP2: 1890 LITRO KT | BQ2: =+IFERROR(VALUE(RIGHT(Tabla12[[#This Row],[B2B]],6)),"") -> 5508 | BR2: =+IFERROR(VLOOKUP(BP2,Auxiliar!$A:$C,2,0),"") -> VALUE LITRO | BS2: =+IFERROR(VLOOKUP(BP2,Auxiliar!$A:$C,3,0),"") -> 1b 12% | BU2: 246 | BV2: CORONA 710 AS | BW2: =+IFERROR(VALUE(RIGHT(Tabla13[[#This Row],[B2B]],6)),"") -> 246 | BX2: =+IFERROR(VLOOKUP(BV2,Auxiliar!$A:$C,2,0),"") -> Corona 710cc | BY2: =+IFERROR(VLOOKUP(BV2,Auxiliar!$A:$C,3,0),"") -> 3b 10% | 169b 0% | CA2: 6 | CB2: CORONA 710 KT | CC2: =+IFERROR(VALUE(RIGHT(Tabla14[[#This Row],[B2B]],6)),"") -> 6 | CD2: =+IFERROR(VLOOKUP(CB2,Auxiliar!$A:$C,2,0),"") -> Corona 710cc | CE2: =+IFERROR(VLOOKUP(CB2,Auxiliar!$A:$C,3,0),"") -> 1b 10% | 85b 0% | CG2: 3897 | CH2: 1890 LATA AS | CI2: =+IFERROR(VALUE(RIGHT(Tabla15[[#This Row],[B2B]],6)),"") -> 3897 | CJ2: =+IFERROR(VLOOKUP(CH2,Auxiliar!$A:$C,2,0),"") -> VALUE LATA | CK2: =+IFERROR(VLOOKUP(CH2,Auxiliar!$A:$C,3,0),"") -> 3b 15% | 100b 18% | CM2: 6 | CN2: SIN ALCOHOL | CO2: 6 | CP2: SIN ALCOHOL | CQ2: 0b 0% | CS2: 246 | CT2: AO, PAT y SA - AS | CU2: =+IFERROR(VALUE(RIGHT(Tabla17[[#This Row],[B2B]],6)),"") -> 246 | CV2: =+IFERROR(VLOOKUP(CT2,Auxiliar!$A:$C,2,0),"") -> PREMIUM | CW2: =+IFERROR(VLOOKUP(CT2,Auxiliar!$A:$C,3,0),"") -> 0b 0% | 5b 2% | 10b 3,5% | 20b 5% | CY2: 6 | CZ2: AO, PAT y SA - K+T | DA2: =+IFERROR(VALUE(RIGHT(Tabla18[[#This Row],[B2B]],6)),"") -> 6 | DB2: =+IFERROR(VLOOKUP(CZ2,Auxiliar!$A:$C,2,0),"") -> PREMIUM | DC2: =+IFERROR(VLOOKUP(CZ2,Auxiliar!$A:$C,3,0),"") -> 0b 0% | 2b 2% | 5b 3,5% | 10b 5% | DE2: 6 | DF2: MICHELOB | DG2: =+IFERROR(VALUE(RIGHT(Tabla19[[#This Row],[B2B]],6)),"") -> 6 | DH2: =+IFERROR(VLOOKUP(DF2,Auxiliar!$A:$C,2,0),"") -> MICHELOB | DI2: =+IFERROR(VLOOKUP(DF2,Auxiliar!$A:$C,3,0),"") -> 1b 7% | 3b 22% | 8b 27% | DK2: 246 | DL2: CORONA PORRON AS | DM2: =+IFERROR(VALUE(RIGHT(Tabla20[[#This Row],[B2B]],6)),"") -> 246 | DN2: =+IFERROR(VLOOKUP(DL2,Auxiliar!$A:$C,2,0),"") -> CORONA PORRON | DO2: =+IFERROR(VLOOKUP(DL2,Auxiliar!$A:$C,3,0),"") -> 3b 5% | 42b 0% | DQ2: 6 | DR2: CORONA PORRON KT | DS2: =+IFERROR(VALUE(RIGHT(Tabla21[[#This Row],[B2B]],6)),"") -> 6 | DT2: =+IFERROR(VLOOKUP(DR2,Auxiliar!$A:$C,2,0),"") -> CORONA PORRON | DU2: =+IFERROR(VLOOKUP(DR2,Auxiliar!$A:$C,3,0),"") -> 1b 5% | 20b 0% | DW2: 5508 | DX2: 1890 LATA KT | DY2: =+IFERROR(VALUE(RIGHT(Tabla22[[#This Row],[B2B]],6)),"") -> 5508 | DZ2: =+IFERROR(VLOOKUP(DX2,Auxiliar!$A:$C,2,0),"") -> VALUE LATA | EA2: =+IFERROR(VLOOKUP(DX2,Auxiliar!$A:$C,3,0),"") -> 1b 15% | 100b 18% | EC2: 5508 | ED2: 1890 LATON | EE2: =+IFERROR(VALUE(RIGHT(Tabla23[[#This Row],[B2B]],6)),"") -> 5508 | EF2: =+IFERROR(VLOOKUP(ED2,Auxiliar!$A:$C,2,0),"") -> VALUE LATON | EG2: =+IFERROR(VLOOKUP(ED2,Auxiliar!$A:$C,3,0),"") -> 1b 10% | 5b 15% | 192b 0% | EI2: 3897 | EJ2: 1890 LATON AS | EK2: =+IFERROR(VALUE(RIGHT(Tabla24[[#This Row],[B2B]],6)),"") -> 3897 | EL2: =+IFERROR(VLOOKUP(EJ2,Auxiliar!$A:$C,2,0),"") -> VALUE LATON | EM2: =+IFERROR(VLOOKUP(EJ2,Auxiliar!$A:$C,3,0),"") -> 3b 10% | 10b 15% | 384b 0% | EO2: 3817 | EP2: LLENADO KT 1 | EQ2: =+IFERROR(VALUE(RIGHT(Tabla25[[#This Row],[B2B]],6)),"") -> 3817 | ER2: =+IFERROR(VLOOKUP(EP2,Auxiliar!$A:$C,2,0),"") -> CORE 2 | ES2: =+IFERROR(VLOOKUP(EP2,Auxiliar!$A:$C,3,0),"") -> 6b 9% | EU2: 3608 | EV2: LLENADO KT 2 | EW2: =+IFERROR(VALUE(RIGHT(Tabla26[[#This Row],[B2B]],6)),"") -> 3608 | EX2: =+IFERROR(VLOOKUP(EV2,Auxiliar!$A:$C,2,0),"") -> CORE 2 | EY2: =+IFERROR(VLOOKUP(EV2,Auxiliar!$A:$C,3,0),"") -> 10b 9% | EZ2: 45 | FA2: LLENADO KT 3 | FB2: =+IFERROR(VALUE(RIGHT(Tabla27[[#This Row],[B2B]],6)),"") -> 45 | FC2: =+IFERROR(VLOOKUP(FA2,Auxiliar!$A:$C,2,0),"") -> CORE 2 | FD2: =+IFERROR(VLOOKUP(FA2,Auxiliar!$A:$C,3,0),"") -> 25b 9% | FG2: =+IFERROR(VALUE(RIGHT(Tabla28[[#This Row],[B2B]],6)),"") | FH2: =+IFERROR(VLOOKUP(FF2,Auxiliar!$A:$C,2,0),"") | FI2: =+IFERROR(VLOOKUP(FF2,Auxiliar!$A:$C,3,0),"") | FL2: =+IFERROR(VALUE(RIGHT(Tabla29[[#This Row],[B2B]],6)),"") | FM2: =+IFERROR(VLOOKUP(FK2,Auxiliar!$A:$C,2,0),"") | FN2: =+IFERROR(VLOOKUP(FK2,Auxiliar!$A:$C,3,0),"") | FQ2: =+IFERROR(VALUE(RIGHT(Tabla30[[#This Row],[B2B]],6)),"") | FR2: =+IFERROR(VLOOKUP(FP2,Auxiliar!$A:$C,2,0),"") | FV2: =+IFERROR(VALUE(RIGHT(Tabla31[[#This Row],[B2B]],6)),"") | FW2: =+IFERROR(VLOOKUP(FU2,Auxiliar!$A:$C,2,0),"") | FX2: =+IFERROR(VLOOKUP(FU2,Auxiliar!$A:$C,3,0),"") | GA2: =+IFERROR(VALUE(RIGHT(Tabla32[[#This Row],[B2B]],6)),"") | GB2: =+IFERROR(VLOOKUP(FZ2,Auxiliar!$A:$C,2,0),"") | GC2: =+IFERROR(VLOOKUP(FZ2,Auxiliar!$A:$C,3,0),"") | GF2: =+IFERROR(VALUE(RIGHT(Tabla33[[#This Row],[B2B]],6)),"") | GG2: =+IFERROR(VLOOKUP(GE2,Auxiliar!$A:$C,2,0),"") | GH2: =+IFERROR(VLOOKUP(GE2,Auxiliar!$A:$C,3,0),"")
A3: 1226 | B3: TIER 1 CORE AS | C3: =+IFERROR(VALUE(RIGHT(Tabla1[[#This Row],[B2B]],6)),"") -> 1226 | D3: =+IFERROR(VLOOKUP(B3,Auxiliar!$A:$C,2,0),"") -> CORE | E3: =+IFERROR(VLOOKUP(B3,Auxiliar!$A:$C,3,0),"") -> 0b 1% | 5b 4% | 10b 5% | 15b 6% | 25b 9% | G3: 2940 | H3: TIER 2 CORE AS | I3: =+IFERROR(VALUE(RIGHT(Tabla2[[#This Row],[B2B]],6)),"") -> 2940 | J3: =+IFERROR(VLOOKUP(H3,Auxiliar!$A:$C,2,0),"") -> CORE | K3: =+IFERROR(VLOOKUP(H3,Auxiliar!$A:$C,3,0),"") -> 0b 1% | 15b 4% | 40b 5% | 60b 9% | M3: 11743 | N3: TIER 3 CORE AS | O3: =+IFERROR(VALUE(RIGHT(Tabla3[[#This Row],[B2B]],6)),"") -> 11743 | P3: =+IFERROR(VLOOKUP(N3,Auxiliar!$A:$C,2,0),"") -> CORE | Q3: =+IFERROR(VLOOKUP(N3,Auxiliar!$A:$C,3,0),"") -> 0b 1% | 60b 4% | 100b 8% | 150b 9% | S3: 15 | T3: TIER 1 CORE KT | U3: =+IFERROR(VALUE(RIGHT(Tabla4[[#This Row],[B2B]],6)),"") -> 15 | V3: =+IFERROR(VLOOKUP(T3,Auxiliar!$A:$C,2,0),"") -> CORE | W3: =+IFERROR(VLOOKUP(T3,Auxiliar!$A:$C,3,0),"") -> 0b 1% | 2b 5% | 4b 6% | Y3: 55 | Z3: TIER 2 CORE KT | AA3: =+IFERROR(VALUE(RIGHT(Tabla5[[#This Row],[B2B]],6)),"") -> 55 | AB3: =+IFERROR(VLOOKUP(Z3,Auxiliar!$A:$C,2,0),"") -> CORE | AC3: =+IFERROR(VLOOKUP(Z3,Auxiliar!$A:$C,3,0),"") -> 0b 1% | 3b 4% | 5b 6% | AE3: 197 | AF3: TIER 3 CORE KT | AG3: =+IFERROR(VALUE(RIGHT(Tabla6[[#This Row],[B2B]],6)),"") -> 197 | AH3: =+IFERROR(VLOOKUP(AF3,Auxiliar!$A:$C,2,0),"") -> CORE | AI3: =+IFERROR(VLOOKUP(AF3,Auxiliar!$A:$C,3,0),"") -> 0b 1% | 6b 5% | 10b 6% | AK3: 15 | AL3: LATONES KT 1 | AM3: =+IFERROR(VALUE(RIGHT(Tabla7[[#This Row],[B2B]],6)),"") -> 15 | AN3: =+IFERROR(VLOOKUP(AL3,Auxiliar!$A:$C,2,0),"") -> LATONES | AO3: =+IFERROR(VLOOKUP(AL3,Auxiliar!$A:$C,3,0),"") -> 1b 4% | 5b 7% | 97b 0% | AQ3: 45 | AR3: LATONES KT 2 | AS3: =+IFERROR(VALUE(RIGHT(Tabla8[[#This Row],[B2B]],6)),"") -> 45 | AT3: =+IFERROR(VLOOKUP(AR3,Auxiliar!$A:$C,2,0),"") -> LATONES | AU3: =+IFERROR(VLOOKUP(AR3,Auxiliar!$A:$C,3,0),"") -> 2b 3% | 4b 5% | 5b 8% | 193 0% | AW3: 437 | AX3: LATONES AS 1 | AY3: =+IFERROR(VALUE(RIGHT(Tabla9[[#This Row],[B2B]],6)),"") -> 437 | AZ3: =+IFERROR(VLOOKUP(AX3,Auxiliar!$A:$C,2,0),"") -> LATONES | BA3: =+IFERROR(VLOOKUP(AX3,Auxiliar!$A:$C,3,0),"") -> 2b 3% | 4b 4% | 6b 5% | 10b 8% | 385b 0% | BC3: 649 | BD3: LATONES AS 2 | BE3: =+IFERROR(VALUE(RIGHT(Tabla10[[#This Row],[B2B]],6)),"") -> 649 | BF3: =+IFERROR(VLOOKUP(BD3,Auxiliar!$A:$C,2,0),"") -> LATONES | BG3: =+IFERROR(VLOOKUP(BD3,Auxiliar!$A:$C,3,0),"") -> 6b 4% | 12b 5% | 15b 8% | 385b 0% | BI3: 3924 | BJ3: 1890 LITRO AS | BK3: =+IFERROR(VALUE(RIGHT(Tabla11[[#This Row],[B2B]],6)),"") -> 3924 | BL3: =+IFERROR(VLOOKUP(BJ3,Auxiliar!$A:$C,2,0),"") -> VALUE LITRO | BM3: =+IFERROR(VLOOKUP(BJ3,Auxiliar!$A:$C,3,0),"") -> 3b 12% | BO3: 5526 | BP3: 1890 LITRO KT | BQ3: =+IFERROR(VALUE(RIGHT(Tabla12[[#This Row],[B2B]],6)),"") -> 5526 | BR3: =+IFERROR(VLOOKUP(BP3,Auxiliar!$A:$C,2,0),"") -> VALUE LITRO | BS3: =+IFERROR(VLOOKUP(BP3,Auxiliar!$A:$C,3,0),"") -> 1b 12% | BU3: 437 | BV3: CORONA 710 AS | BW3: =+IFERROR(VALUE(RIGHT(Tabla13[[#This Row],[B2B]],6)),"") -> 437 | BX3: =+IFERROR(VLOOKUP(BV3,Auxiliar!$A:$C,2,0),"") -> Corona 710cc | BY3: =+IFERROR(VLOOKUP(BV3,Auxiliar!$A:$C,3,0),"") -> 3b 10% | 169b 0% | CA3: 15 | CB3: CORONA 710 KT | CC3: =+IFERROR(VALUE(RIGHT(Tabla14[[#This Row],[B2B]],6)),"") -> 15 | CD3: =+IFERROR(VLOOKUP(CB3,Auxiliar!$A:$C,2,0),"") -> Corona 710cc | CE3: =+IFERROR(VLOOKUP(CB3,Auxiliar!$A:$C,3,0),"") -> 1b 10% | 85b 0% | CG3: 3924 | CH3: 1890 LATA AS | CI3: =+IFERROR(VALUE(RIGHT(Tabla15[[#This Row],[B2B]],6)),"") -> 3924 | CJ3: =+IFERROR(VLOOKUP(CH3,Auxiliar!$A:$C,2,0),"") -> VALUE LATA | CK3: =+IFERROR(VLOOKUP(CH3,Auxiliar!$A:$C,3,0),"") -> 3b 15% | 100b 18% | CM3: 15 | CN3: SIN ALCOHOL | CO3: 15 | CP3: SIN ALCOHOL | CQ3: 0b 0% | CS3: 437 | CT3: AO, PAT y SA - AS | CU3: =+IFERROR(VALUE(RIGHT(Tabla17[[#This Row],[B2B]],6)),"") -> 437 | CV3: =+IFERROR(VLOOKUP(CT3,Auxiliar!$A:$C,2,0),"") -> PREMIUM | CW3: =+IFERROR(VLOOKUP(CT3,Auxiliar!$A:$C,3,0),"") -> 0b 0% | 5b 2% | 10b 3,5% | 20b 5% | CY3: 15 | CZ3: AO, PAT y SA - K+T | DA3: =+IFERROR(VALUE(RIGHT(Tabla18[[#This Row],[B2B]],6)),"") -> 15 | DB3: =+IFERROR(VLOOKUP(CZ3,Auxiliar!$A:$C,2,0),"") -> PREMIUM | DC3: =+IFERROR(VLOOKUP(CZ3,Auxiliar!$A:$C,3,0),"") -> 0b 0% | 2b 2% | 5b 3,5% | 10b 5% | DE3: 15 | DF3: MICHELOB | DG3: =+IFERROR(VALUE(RIGHT(Tabla19[[#This Row],[B2B]],6)),"") -> 15 | DH3: =+IFERROR(VLOOKUP(DF3,Auxiliar!$A:$C,2,0),"") -> MICHELOB | DI3: =+IFERROR(VLOOKUP(DF3,Auxiliar!$A:$C,3,0),"") -> 1b 7% | 3b 22% | 8b 27% | DK3: 437 | DL3: CORONA PORRON AS | DM3: =+IFERROR(VALUE(RIGHT(Tabla20[[#This Row],[B2B]],6)),"") -> 437 | DN3: =+IFERROR(VLOOKUP(DL3,Auxiliar!$A:$C,2,0),"") -> CORONA PORRON | DO3: =+IFERROR(VLOOKUP(DL3,Auxiliar!$A:$C,3,0),"") -> 3b 5% | 42b 0% | DQ3: 15 | DR3: CORONA PORRON KT | DS3: =+IFERROR(VALUE(RIGHT(Tabla21[[#This Row],[B2B]],6)),"") -> 15 | DT3: =+IFERROR(VLOOKUP(DR3,Auxiliar!$A:$C,2,0),"") -> CORONA PORRON | DU3: =+IFERROR(VLOOKUP(DR3,Auxiliar!$A:$C,3,0),"") -> 1b 5% | 20b 0% | DW3: 5526 | DX3: 1890 LATA KT | DY3: =+IFERROR(VALUE(RIGHT(Tabla22[[#This Row],[B2B]],6)),"") -> 5526 | DZ3: =+IFERROR(VLOOKUP(DX3,Auxiliar!$A:$C,2,0),"") -> VALUE LATA | EA3: =+IFERROR(VLOOKUP(DX3,Auxiliar!$A:$C,3,0),"") -> 1b 15% | 100b 18% | EC3: 5526 | ED3: 1890 LATON | EE3: =+IFERROR(VALUE(RIGHT(Tabla23[[#This Row],[B2B]],6)),"") -> 5526 | EF3: =+IFERROR(VLOOKUP(ED3,Auxiliar!$A:$C,2,0),"") -> VALUE LATON | EG3: =+IFERROR(VLOOKUP(ED3,Auxiliar!$A:$C,3,0),"") -> 1b 10% | 5b 15% | 192b 0% | EI3: 3936 | EJ3: 1890 LATON AS | EK3: =+IFERROR(VALUE(RIGHT(Tabla24[[#This Row],[B2B]],6)),"") -> 3936 | EL3: =+IFERROR(VLOOKUP(EJ3,Auxiliar!$A:$C,2,0),"") -> VALUE LATON | EM3: =+IFERROR(VLOOKUP(EJ3,Auxiliar!$A:$C,3,0),"") -> 3b 10% | 10b 15% | 384b 0% | EQ3: =+IFERROR(VALUE(RIGHT(Tabla25[[#This Row],[B2B]],6)),"") | ER3: =+IFERROR(VLOOKUP(EP3,Auxiliar!$A:$C,2,0),"") | ES3: =+IFERROR(VLOOKUP(EP3,Auxiliar!$A:$C,3,0),"") | EW3: =+IFERROR(VALUE(RIGHT(Tabla26[[#This Row],[B2B]],6)),"") | EX3: =+IFERROR(VLOOKUP(EV3,Auxiliar!$A:$C,2,0),"") | EY3: =+IFERROR(VLOOKUP(EV3,Auxiliar!$A:$C,3,0),"") | EZ3: 312 | FA3: LLENADO KT 3 | FB3: =+IFERROR(VALUE(RIGHT(Tabla27[[#This Row],[B2B]],6)),"") -> 312 | FC3: =+IFERROR(VLOOKUP(FA3,Auxiliar!$A:$C,2,0),"") -> CORE 2 | FD3: =+IFERROR(VLOOKUP(FA3,Auxiliar!$A:$C,3,0),"") -> 25b 9% | FG3: =+IFERROR(VALUE(RIGHT(Tabla28[[#This Row],[B2B]],6)),"") | FH3: =+IFERROR(VLOOKUP(FF3,Auxiliar!$A:$C,2,0),"") | FI3: =+IFERROR(VLOOKUP(FF3,Auxiliar!$A:$C,3,0),"") | FL3: =+IFERROR(VALUE(RIGHT(Tabla29[[#This Row],[B2B]],6)),"") | FM3: =+IFERROR(VLOOKUP(FK3,Auxiliar!$A:$C,2,0),"") | FN3: =+IFERROR(VLOOKUP(FK3,Auxiliar!$A:$C,3,0),"") | FQ3: =+IFERROR(VALUE(RIGHT(Tabla30[[#This Row],[B2B]],6)),"") | FR3: =+IFERROR(VLOOKUP(FP3,Auxiliar!$A:$C,2,0),"") | FV3: =+IFERROR(VALUE(RIGHT(Tabla31[[#This Row],[B2B]],6)),"") | FW3: =+IFERROR(VLOOKUP(FU3,Auxiliar!$A:$C,2,0),"") | FX3: =+IFERROR(VLOOKUP(FU3,Auxiliar!$A:$C,3,0),"") | GA3: =+IFERROR(VALUE(RIGHT(Tabla32[[#This Row],[B2B]],6)),"") | GB3: =+IFERROR(VLOOKUP(FZ3,Auxiliar!$A:$C,2,0),"") | GC3: =+IFERROR(VLOOKUP(FZ3,Auxiliar!$A:$C,3,0),"") | GF3: =+IFERROR(VALUE(RIGHT(Tabla33[[#This Row],[B2B]],6)),"") | GG3: =+IFERROR(VLOOKUP(GE3,Auxiliar!$A:$C,2,0),"") | GH3: =+IFERROR(VLOOKUP(GE3,Auxiliar!$A:$C,3,0),"")
A4: 2451 | B4: TIER 1 CORE AS | C4: =+IFERROR(VALUE(RIGHT(Tabla1[[#This Row],[B2B]],6)),"") -> 2451 | D4: =+IFERROR(VLOOKUP(B4,Auxiliar!$A:$C,2,0),"") -> CORE | E4: =+IFERROR(VLOOKUP(B4,Auxiliar!$A:$C,3,0),"") -> 0b 1% | 5b 4% | 10b 5% | 15b 6% | 25b 9% | G4: 3474 | H4: TIER 2 CORE AS | I4: =+IFERROR(VALUE(RIGHT(Tabla2[[#This Row],[B2B]],6)),"") -> 3474 | J4: =+IFERROR(VLOOKUP(H4,Auxiliar!$A:$C,2,0),"") -> CORE | K4: =+IFERROR(VLOOKUP(H4,Auxiliar!$A:$C,3,0),"") -> 0b 1% | 15b 4% | 40b 5% | 60b 9% | O4: =+IFERROR(VALUE(RIGHT(Tabla3[[#This Row],[B2B]],6)),"") | P4: =+IFERROR(VLOOKUP(N4,Auxiliar!$A:$C,2,0),"") | Q4: =+IFERROR(VLOOKUP(N4,Auxiliar!$A:$C,3,0),"") | S4: 33 | T4: TIER 1 CORE KT | U4: =+IFERROR(VALUE(RIGHT(Tabla4[[#This Row],[B2B]],6)),"") -> 33 | V4: =+IFERROR(VLOOKUP(T4,Auxiliar!$A:$C,2,0),"") -> CORE | W4: =+IFERROR(VLOOKUP(T4,Auxiliar!$A:$C,3,0),"") -> 0b 1% | 2b 5% | 4b 6% | Y4: 71 | Z4: TIER 2 CORE KT | AA4: =+IFERROR(VALUE(RIGHT(Tabla5[[#This Row],[B2B]],6)),"") -> 71 | AB4: =+IFERROR(VLOOKUP(Z4,Auxiliar!$A:$C,2,0),"") -> CORE | AC4: =+IFERROR(VLOOKUP(Z4,Auxiliar!$A:$C,3,0),"") -> 0b 1% | 3b 4% | 5b 6% | AE4: 255 | AF4: TIER 3 CORE KT | AG4: =+IFERROR(VALUE(RIGHT(Tabla6[[#This Row],[B2B]],6)),"") -> 255 | AH4: =+IFERROR(VLOOKUP(AF4,Auxiliar!$A:$C,2,0),"") -> CORE | AI4: =+IFERROR(VLOOKUP(AF4,Auxiliar!$A:$C,3,0),"") -> 0b 1% | 6b 5% | 10b 6% | AK4: 33 | AL4: LATONES KT 1 | AM4: =+IFERROR(VALUE(RIGHT(Tabla7[[#This Row],[B2B]],6)),"") -> 33 | AN4: =+IFERROR(VLOOKUP(AL4,Auxiliar!$A:$C,2,0),"") -> LATONES | AO4: =+IFERROR(VLOOKUP(AL4,Auxiliar!$A:$C,3,0),"") -> 1b 4% | 5b 7% | 97b 0% | AQ4: 55 | AR4: LATONES KT 2 | AS4: =+IFERROR(VALUE(RIGHT(Tabla8[[#This Row],[B2B]],6)),"") -> 55 | AT4: =+IFERROR(VLOOKUP(AR4,Auxiliar!$A:$C,2,0),"") -> LATONES | AU4: =+IFERROR(VLOOKUP(AR4,Auxiliar!$A:$C,3,0),"") -> 2b 3% | 4b 5% | 5b 8% | 193 0% | AW4: 2822 | AX4: LATONES AS 1 | AY4: =+IFERROR(VALUE(RIGHT(Tabla9[[#This Row],[B2B]],6)),"") -> 2822 | AZ4: =+IFERROR(VLOOKUP(AX4,Auxiliar!$A:$C,2,0),"") -> LATONES | BA4: =+IFERROR(VLOOKUP(AX4,Auxiliar!$A:$C,3,0),"") -> 2b 3% | 4b 4% | 6b 5% | 10b 8% | 385b 0% | BC4: 1000 | BD4: LATONES AS 2 | BE4: =+IFERROR(VALUE(RIGHT(Tabla10[[#This Row],[B2B]],6)),"") -> 1000 | BF4: =+IFERROR(VLOOKUP(BD4,Auxiliar!$A:$C,2,0),"") -> LATONES | BG4: =+IFERROR(VLOOKUP(BD4,Auxiliar!$A:$C,3,0),"") -> 6b 4% | 12b 5% | 15b 8% | 385b 0% | BI4: 3936 | BJ4: 1890 LITRO AS | BK4: =+IFERROR(VALUE(RIGHT(Tabla11[[#This Row],[B2B]],6)),"") -> 3936 | BL4: =+IFERROR(VLOOKUP(BJ4,Auxiliar!$A:$C,2,0),"") -> VALUE LITRO | BM4: =+IFERROR(VLOOKUP(BJ4,Auxiliar!$A:$C,3,0),"") -> 3b 12% | BO4: 5535 | BP4: 1890 LITRO KT | BQ4: =+IFERROR(VALUE(RIGHT(Tabla12[[#This Row],[B2B]],6)),"") -> 5535 | BR4: =+IFERROR(VLOOKUP(BP4,Auxiliar!$A:$C,2,0),"") -> VALUE LITRO | BS4: =+IFERROR(VLOOKUP(BP4,Auxiliar!$A:$C,3,0),"") -> 1b 12% | BU4: 649 | BV4: CORONA 710 AS | BW4: =+IFERROR(VALUE(RIGHT(Tabla13[[#This Row],[B2B]],6)),"") -> 649 | BX4: =+IFERROR(VLOOKUP(BV4,Auxiliar!$A:$C,2,0),"") -> Corona 710cc | BY4: =+IFERROR(VLOOKUP(BV4,Auxiliar!$A:$C,3,0),"") -> 3b 10% | 169b 0% | CA4: 27 | CB4: CORONA 710 KT | CC4: =+IFERROR(VALUE(RIGHT(Tabla14[[#This Row],[B2B]],6)),"") -> 27 | CD4: =+IFERROR(VLOOKUP(CB4,Auxiliar!$A:$C,2,0),"") -> Corona 710cc | CE4: =+IFERROR(VLOOKUP(CB4,Auxiliar!$A:$C,3,0),"") -> 1b 10% | 85b 0% | CG4: 3936 | CH4: 1890 LATA AS | CI4: =+IFERROR(VALUE(RIGHT(Tabla15[[#This Row],[B2B]],6)),"") -> 3936 | CJ4: =+IFERROR(VLOOKUP(CH4,Auxiliar!$A:$C,2,0),"") -> VALUE LATA | CK4: =+IFERROR(VLOOKUP(CH4,Auxiliar!$A:$C,3,0),"") -> 3b 15% | 100b 18% | CM4: 27 | CN4: SIN ALCOHOL | CO4: 27 | CP4: SIN ALCOHOL | CQ4: 0b 0% | CS4: 649 | CT4: AO, PAT y SA - AS | CU4: =+IFERROR(VALUE(RIGHT(Tabla17[[#This Row],[B2B]],6)),"") -> 649 | CV4: =+IFERROR(VLOOKUP(CT4,Auxiliar!$A:$C,2,0),"") -> PREMIUM | CW4: =+IFERROR(VLOOKUP(CT4,Auxiliar!$A:$C,3,0),"") -> 0b 0% | 5b 2% | 10b 3,5% | 20b 5% | CY4: 27 | CZ4: AO, PAT y SA - K+T | DA4: =+IFERROR(VALUE(RIGHT(Tabla18[[#This Row],[B2B]],6)),"") -> 27 | DB4: =+IFERROR(VLOOKUP(CZ4,Auxiliar!$A:$C,2,0),"") -> PREMIUM | DC4: =+IFERROR(VLOOKUP(CZ4,Auxiliar!$A:$C,3,0),"") -> 0b 0% | 2b 2% | 5b 3,5% | 10b 5% | DE4: 27 | DF4: MICHELOB | DG4: =+IFERROR(VALUE(RIGHT(Tabla19[[#This Row],[B2B]],6)),"") -> 27 | DH4: =+IFERROR(VLOOKUP(DF4,Auxiliar!$A:$C,2,0),"") -> MICHELOB | DI4: =+IFERROR(VLOOKUP(DF4,Auxiliar!$A:$C,3,0),"") -> 1b 7% | 3b 22% | 8b 27% | DK4: 649 | DL4: CORONA PORRON AS | DM4: =+IFERROR(VALUE(RIGHT(Tabla20[[#This Row],[B2B]],6)),"") -> 649 | DN4: =+IFERROR(VLOOKUP(DL4,Auxiliar!$A:$C,2,0),"") -> CORONA PORRON | DO4: =+IFERROR(VLOOKUP(DL4,Auxiliar!$A:$C,3,0),"") -> 3b 5% | 42b 0% | DQ4: 27 | DR4: CORONA PORRON KT | DS4: =+IFERROR(VALUE(RIGHT(Tabla21[[#This Row],[B2B]],6)),"") -> 27 | DT4: =+IFERROR(VLOOKUP(DR4,Auxiliar!$A:$C,2,0),"") -> CORONA PORRON | DU4: =+IFERROR(VLOOKUP(DR4,Auxiliar!$A:$C,3,0),"") -> 1b 5% | 20b 0% | DW4: 5535 | DX4: 1890 LATA KT | DY4: =+IFERROR(VALUE(RIGHT(Tabla22[[#This Row],[B2B]],6)),"") -> 5535 | DZ4: =+IFERROR(VLOOKUP(DX4,Auxiliar!$A:$C,2,0),"") -> VALUE LATA | EA4: =+IFERROR(VLOOKUP(DX4,Auxiliar!$A:$C,3,0),"") -> 1b 15% | 100b 18% | EC4: 5535 | ED4: 1890 LATON | EE4: =+IFERROR(VALUE(RIGHT(Tabla23[[#This Row],[B2B]],6)),"") -> 5535 | EF4: =+IFERROR(VLOOKUP(ED4,Auxiliar!$A:$C,2,0),"") -> VALUE LATON | EG4: =+IFERROR(VLOOKUP(ED4,Auxiliar!$A:$C,3,0),"") -> 1b 10% | 5b 15% | 192b 0% | EI4: 4057 | EJ4: 1890 LATON AS | EK4: =+IFERROR(VALUE(RIGHT(Tabla24[[#This Row],[B2B]],6)),"") -> 4057 | EL4: =+IFERROR(VLOOKUP(EJ4,Auxiliar!$A:$C,2,0),"") -> VALUE LATON | EM4: =+IFERROR(VLOOKUP(EJ4,Auxiliar!$A:$C,3,0),"") -> 3b 10% | 10b 15% | 384b 0% | EQ4: =+IFERROR(VALUE(RIGHT(Tabla25[[#This Row],[B2B]],6)),"") | ER4: =+IFERROR(VLOOKUP(EP4,Auxiliar!$A:$C,2,0),"") | ES4: =+IFERROR(VLOOKUP(EP4,Auxiliar!$A:$C,3,0),"") | EW4: =+IFERROR(VALUE(RIGHT(Tabla26[[#This Row],[B2B]],6)),"") | EX4: =+IFERROR(VLOOKUP(EV4,Auxiliar!$A:$C,2,0),"") | EY4: =+IFERROR(VLOOKUP(EV4,Auxiliar!$A:$C,3,0),"") | EZ4: 1793 | FA4: LLENADO KT 3 | FB4: =+IFERROR(VALUE(RIGHT(Tabla27[[#This Row],[B2B]],6)),"") -> 1793 | FC4: =+IFERROR(VLOOKUP(FA4,Auxiliar!$A:$C,2,0),"") -> CORE 2 | FD4: =+IFERROR(VLOOKUP(FA4,Auxiliar!$A:$C,3,0),"") -> 25b 9% | FG4: =+IFERROR(VALUE(RIGHT(Tabla28[[#This Row],[B2B]],6)),"") | FH4: =+IFERROR(VLOOKUP(FF4,Auxiliar!$A:$C,2,0),"") | FI4: =+IFERROR(VLOOKUP(FF4,Auxiliar!$A:$C,3,0),"") | FL4: =+IFERROR(VALUE(RIGHT(Tabla29[[#This Row],[B2B]],6)),"") | FM4: =+IFERROR(VLOOKUP(FK4,Auxiliar!$A:$C,2,0),"") | FN4: =+IFERROR(VLOOKUP(FK4,Auxiliar!$A:$C,3,0),"") | FQ4: =+IFERROR(VALUE(RIGHT(Tabla30[[#This Row],[B2B]],6)),"") | FR4: =+IFERROR(VLOOKUP(FP4,Auxiliar!$A:$C,2,0),"") | FV4: =+IFERROR(VALUE(RIGHT(Tabla31[[#This Row],[B2B]],6)),"") | FW4: =+IFERROR(VLOOKUP(FU4,Auxiliar!$A:$C,2,0),"") | FX4: =+IFERROR(VLOOKUP(FU4,Auxiliar!$A:$C,3,0),"") | GA4: =+IFERROR(VALUE(RIGHT(Tabla32[[#This Row],[B2B]],6)),"") | GB4: =+IFERROR(VLOOKUP(FZ4,Auxiliar!$A:$C,2,0),"") | GC4: =+IFERROR(VLOOKUP(FZ4,Auxiliar!$A:$C,3,0),"") | GF4: =+IFERROR(VALUE(RIGHT(Tabla33[[#This Row],[B2B]],6)),"") | GG4: =+IFERROR(VLOOKUP(GE4,Auxiliar!$A:$C,2,0),"") | GH4: =+IFERROR(VLOOKUP(GE4,Auxiliar!$A:$C,3,0),"")
A5: 2669 | B5: TIER 1 CORE AS | C5: =+IFERROR(VALUE(RIGHT(Tabla1[[#This Row],[B2B]],6)),"") -> 2669 | D5: =+IFERROR(VLOOKUP(B5,Auxiliar!$A:$C,2,0),"") -> CORE | E5: =+IFERROR(VLOOKUP(B5,Auxiliar!$A:$C,3,0),"") -> 0b 1% | 5b 4% | 10b 5% | 15b 6% | 25b 9% | G5: 3850 | H5: TIER 2 CORE AS | I5: =+IFERROR(VALUE(RIGHT(Tabla2[[#This Row],[B2B]],6)),"") -> 3850 | J5: =+IFERROR(VLOOKUP(H5,Auxiliar!$A:$C,2,0),"") -> CORE | K5: =+IFERROR(VLOOKUP(H5,Auxiliar!$A:$C,3,0),"") -> 0b 1% | 15b 4% | 40b 5% | 60b 9% | O5: =+IFERROR(VALUE(RIGHT(Tabla3[[#This Row],[B2B]],6)),"") | P5: =+IFERROR(VLOOKUP(N5,Auxiliar!$A:$C,2,0),"") | Q5: =+IFERROR(VLOOKUP(N5,Auxiliar!$A:$C,3,0),"") | S5: 63 | T5: TIER 1 CORE KT | U5: =+IFERROR(VALUE(RIGHT(Tabla4[[#This Row],[B2B]],6)),"") -> 63 | V5: =+IFERROR(VLOOKUP(T5,Auxiliar!$A:$C,2,0),"") -> CORE | W5: =+IFERROR(VLOOKUP(T5,Auxiliar!$A:$C,3,0),"") -> 0b 1% | 2b 5% | 4b 6% | Y5: 132 | Z5: TIER 2 CORE KT | AA5: =+IFERROR(VALUE(RIGHT(Tabla5[[#This Row],[B2B]],6)),"") -> 132 | AB5: =+IFERROR(VLOOKUP(Z5,Auxiliar!$A:$C,2,0),"") -> CORE | AC5: =+IFERROR(VLOOKUP(Z5,Auxiliar!$A:$C,3,0),"") -> 0b 1% | 3b 4% | 5b 6% | AE5: 312 | AF5: TIER 3 CORE KT | AG5: =+IFERROR(VALUE(RIGHT(Tabla6[[#This Row],[B2B]],6)),"") -> 312 | AH5: =+IFERROR(VLOOKUP(AF5,Auxiliar!$A:$C,2,0),"") -> CORE | AI5: =+IFERROR(VLOOKUP(AF5,Auxiliar!$A:$C,3,0),"") -> 0b 1% | 6b 5% | 10b 6% | AK5: 63 | AL5: LATONES KT 1 | AM5: =+IFERROR(VALUE(RIGHT(Tabla7[[#This Row],[B2B]],6)),"") -> 63 | AN5: =+IFERROR(VLOOKUP(AL5,Auxiliar!$A:$C,2,0),"") -> LATONES | AO5: =+IFERROR(VLOOKUP(AL5,Auxiliar!$A:$C,3,0),"") -> 1b 4% | 5b 7% | 97b 0% | AQ5: 132 | AR5: LATONES KT 2 | AS5: =+IFERROR(VALUE(RIGHT(Tabla8[[#This Row],[B2B]],6)),"") -> 132 | AT5: =+IFERROR(VLOOKUP(AR5,Auxiliar!$A:$C,2,0),"") -> LATONES | AU5: =+IFERROR(VLOOKUP(AR5,Auxiliar!$A:$C,3,0),"") -> 2b 3% | 4b 5% | 5b 8% | 193 0% | AW5: 2905 | AX5: LATONES AS 1 | AY5: =+IFERROR(VALUE(RIGHT(Tabla9[[#This Row],[B2B]],6)),"") -> 2905 | AZ5: =+IFERROR(VLOOKUP(AX5,Auxiliar!$A:$C,2,0),"") -> LATONES | BA5: =+IFERROR(VLOOKUP(AX5,Auxiliar!$A:$C,3,0),"") -> 2b 3% | 4b 4% | 6b 5% | 10b 8% | 385b 0% | BC5: 1226 | BD5: LATONES AS 2 | BE5: =+IFERROR(VALUE(RIGHT(Tabla10[[#This Row],[B2B]],6)),"") -> 1226 | BF5: =+IFERROR(VLOOKUP(BD5,Auxiliar!$A:$C,2,0),"") -> LATONES | BG5: =+IFERROR(VLOOKUP(BD5,Auxiliar!$A:$C,3,0),"") -> 6b 4% | 12b 5% | 15b 8% | 385b 0% | BI5: 4057 | BJ5: 1890 LITRO AS | BK5: =+IFERROR(VALUE(RIGHT(Tabla11[[#This Row],[B2B]],6)),"") -> 4057 | BL5: =+IFERROR(VLOOKUP(BJ5,Auxiliar!$A:$C,2,0),"") -> VALUE LITRO | BM5: =+IFERROR(VLOOKUP(BJ5,Auxiliar!$A:$C,3,0),"") -> 3b 12% | BO5: 5543 | BP5: 1890 LITRO KT | BQ5: =+IFERROR(VALUE(RIGHT(Tabla12[[#This Row],[B2B]],6)),"") -> 5543 | BR5: =+IFERROR(VLOOKUP(BP5,Auxiliar!$A:$C,2,0),"") -> VALUE LITRO | BS5: =+IFERROR(VLOOKUP(BP5,Auxiliar!$A:$C,3,0),"") -> 1b 12% | BU5: 1000 | BV5: CORONA 710 AS | BW5: =+IFERROR(VALUE(RIGHT(Tabla13[[#This Row],[B2B]],6)),"") -> 1000 | BX5: =+IFERROR(VLOOKUP(BV5,Auxiliar!$A:$C,2,0),"") -> Corona 710cc | BY5: =+IFERROR(VLOOKUP(BV5,Auxiliar!$A:$C,3,0),"") -> 3b 10% | 169b 0% | CA5: 39 | CB5: CORONA 710 KT | CC5: =+IFERROR(VALUE(RIGHT(Tabla14[[#This Row],[B2B]],6)),"") -> 39 | CD5: =+IFERROR(VLOOKUP(CB5,Auxiliar!$A:$C,2,0),"") -> Corona 710cc | CE5: =+IFERROR(VLOOKUP(CB5,Auxiliar!$A:$C,3,0),"") -> 1b 10% | 85b 0% | CG5: 4057 | CH5: 1890 LATA AS | CI5: =+IFERROR(VALUE(RIGHT(Tabla15[[#This Row],[B2B]],6)),"") -> 4057 | CJ5: =+IFERROR(VLOOKUP(CH5,Auxiliar!$A:$C,2,0),"") -> VALUE LATA | CK5: =+IFERROR(VLOOKUP(CH5,Auxiliar!$A:$C,3,0),"") -> 3b 15% | 100b 18% | CM5: 39 | CN5: SIN ALCOHOL | CO5: 39 | CP5: SIN ALCOHOL | CQ5: 0b 0% | CS5: 1000 | CT5: AO, PAT y SA - AS | CU5: =+IFERROR(VALUE(RIGHT(Tabla17[[#This Row],[B2B]],6)),"") -> 1000 | CV5: =+IFERROR(VLOOKUP(CT5,Auxiliar!$A:$C,2,0),"") -> PREMIUM | CW5: =+IFERROR(VLOOKUP(CT5,Auxiliar!$A:$C,3,0),"") -> 0b 0% | 5b 2% | 10b 3,5% | 20b 5% | CY5: 39 | CZ5: AO, PAT y SA - K+T | DA5: =+IFERROR(VALUE(RIGHT(Tabla18[[#This Row],[B2B]],6)),"") -> 39 | DB5: =+IFERROR(VLOOKUP(CZ5,Auxiliar!$A:$C,2,0),"") -> PREMIUM | DC5: =+IFERROR(VLOOKUP(CZ5,Auxiliar!$A:$C,3,0),"") -> 0b 0% | 2b 2% | 5b 3,5% | 10b 5% | DE5: 39 | DF5: MICHELOB | DG5: =+IFERROR(VALUE(RIGHT(Tabla19[[#This Row],[B2B]],6)),"") -> 39 | DH5: =+IFERROR(VLOOKUP(DF5,Auxiliar!$A:$C,2,0),"") -> MICHELOB | DI5: =+IFERROR(VLOOKUP(DF5,Auxiliar!$A:$C,3,0),"") -> 1b 7% | 3b 22% | 8b 27% | DK5: 1000 | DL5: CORONA PORRON AS | DM5: =+IFERROR(VALUE(RIGHT(Tabla20[[#This Row],[B2B]],6)),"") -> 1000 | DN5: =+IFERROR(VLOOKUP(DL5,Auxiliar!$A:$C,2,0),"") -> CORONA PORRON | DO5: =+IFERROR(VLOOKUP(DL5,Auxiliar!$A:$C,3,0),"") -> 3b 5% | 42b 0% | DQ5: 39 | DR5: CORONA PORRON KT | DS5: =+IFERROR(VALUE(RIGHT(Tabla21[[#This Row],[B2B]],6)),"") -> 39 | DT5: =+IFERROR(VLOOKUP(DR5,Auxiliar!$A:$C,2,0),"") -> CORONA PORRON | DU5: =+IFERROR(VLOOKUP(DR5,Auxiliar!$A:$C,3,0),"") -> 1b 5% | 20b 0% | DW5: 5543 | DX5: 1890 LATA KT | DY5: =+IFERROR(VALUE(RIGHT(Tabla22[[#This Row],[B2B]],6)),"") -> 5543 | DZ5: =+IFERROR(VLOOKUP(DX5,Auxiliar!$A:$C,2,0),"") -> VALUE LATA | EA5: =+IFERROR(VLOOKUP(DX5,Auxiliar!$A:$C,3,0),"") -> 1b 15% | 100b 18% | EC5: 5543 | ED5: 1890 LATON | EE5: =+IFERROR(VALUE(RIGHT(Tabla23[[#This Row],[B2B]],6)),"") -> 5543 | EF5: =+IFERROR(VLOOKUP(ED5,Auxiliar!$A:$C,2,0),"") -> VALUE LATON | EG5: =+IFERROR(VLOOKUP(ED5,Auxiliar!$A:$C,3,0),"") -> 1b 10% | 5b 15% | 192b 0% | EI5: 4328 | EJ5: 1890 LATON AS | EK5: =+IFERROR(VALUE(RIGHT(Tabla24[[#This Row],[B2B]],6)),"") -> 4328 | EL5: =+IFERROR(VLOOKUP(EJ5,Auxiliar!$A:$C,2,0),"") -> VALUE LATON | EM5: =+IFERROR(VLOOKUP(EJ5,Auxiliar!$A:$C,3,0),"") -> 3b 10% | 10b 15% | 384b 0% | EQ5: =+IFERROR(VALUE(RIGHT(Tabla25[[#This Row],[B2B]],6)),"") | ER5: =+IFERROR(VLOOKUP(EP5,Auxiliar!$A:$C,2,0),"") | ES5: =+IFERROR(VLOOKUP(EP5,Auxiliar!$A:$C,3,0),"") | EW5: =+IFERROR(VALUE(RIGHT(Tabla26[[#This Row],[B2B]],6)),"") | EX5: =+IFERROR(VLOOKUP(EV5,Auxiliar!$A:$C,2,0),"") | EY5: =+IFERROR(VLOOKUP(EV5,Auxiliar!$A:$C,3,0),"") | EZ5: 1953 | FA5: LLENADO KT 3 | FB5: =+IFERROR(VALUE(RIGHT(Tabla27[[#This Row],[B2B]],6)),"") -> 1953 | FC5: =+IFERROR(VLOOKUP(FA5,Auxiliar!$A:$C,2,0),"") -> CORE 2 | FD5: =+IFERROR(VLOOKUP(FA5,Auxiliar!$A:$C,3,0),"") -> 25b 9% | FG5: =+IFERROR(VALUE(RIGHT(Tabla28[[#This Row],[B2B]],6)),"") | FH5: =+IFERROR(VLOOKUP(FF5,Auxiliar!$A:$C,2,0),"") | FI5: =+IFERROR(VLOOKUP(FF5,Auxiliar!$A:$C,3,0),"") | FL5: =+IFERROR(VALUE(RIGHT(Tabla29[[#This Row],[B2B]],6)),"") | FM5: =+IFERROR(VLOOKUP(FK5,Auxiliar!$A:$C,2,0),"") | FN5: =+IFERROR(VLOOKUP(FK5,Auxiliar!$A:$C,3,0),"") | FQ5: =+IFERROR(VALUE(RIGHT(Tabla30[[#This Row],[B2B]],6)),"") | FR5: =+IFERROR(VLOOKUP(FP5,Auxiliar!$A:$C,2,0),"") | FV5: =+IFERROR(VALUE(RIGHT(Tabla31[[#This Row],[B2B]],6)),"") | FW5: =+IFERROR(VLOOKUP(FU5,Auxiliar!$A:$C,2,0),"") | FX5: =+IFERROR(VLOOKUP(FU5,Auxiliar!$A:$C,3,0),"") | GA5: =+IFERROR(VALUE(RIGHT(Tabla32[[#This Row],[B2B]],6)),"") | GB5: =+IFERROR(VLOOKUP(FZ5,Auxiliar!$A:$C,2,0),"") | GC5: =+IFERROR(VLOOKUP(FZ5,Auxiliar!$A:$C,3,0),"") | GF5: =+IFERROR(VALUE(RIGHT(Tabla33[[#This Row],[B2B]],6)),"") | GG5: =+IFERROR(VLOOKUP(GE5,Auxiliar!$A:$C,2,0),"") | GH5: =+IFERROR(VLOOKUP(GE5,Auxiliar!$A:$C,3,0),"")
A6: 2767 | B6: TIER 1 CORE AS | C6: =+IFERROR(VALUE(RIGHT(Tabla1[[#This Row],[B2B]],6)),"") -> 2767 | D6: =+IFERROR(VLOOKUP(B6,Auxiliar!$A:$C,2,0),"") -> CORE | E6: =+IFERROR(VLOOKUP(B6,Auxiliar!$A:$C,3,0),"") -> 0b 1% | 5b 4% | 10b 5% | 15b 6% | 25b 9% | G6: 3897 | H6: TIER 2 CORE AS | I6: =+IFERROR(VALUE(RIGHT(Tabla2[[#This Row],[B2B]],6)),"") -> 3897 | J6: =+IFERROR(VLOOKUP(H6,Auxiliar!$A:$C,2,0),"") -> CORE | K6: =+IFERROR(VLOOKUP(H6,Auxiliar!$A:$C,3,0),"") -> 0b 1% | 15b 4% | 40b 5% | 60b 9% | O6: =+IFERROR(VALUE(RIGHT(Tabla3[[#This Row],[B2B]],6)),"") | P6: =+IFERROR(VLOOKUP(N6,Auxiliar!$A:$C,2,0),"") | Q6: =+IFERROR(VLOOKUP(N6,Auxiliar!$A:$C,3,0),"") | S6: 72 | T6: TIER 1 CORE KT | U6: =+IFERROR(VALUE(RIGHT(Tabla4[[#This Row],[B2B]],6)),"") -> 72 | V6: =+IFERROR(VLOOKUP(T6,Auxiliar!$A:$C,2,0),"") -> CORE | W6: =+IFERROR(VLOOKUP(T6,Auxiliar!$A:$C,3,0),"") -> 0b 1% | 2b 5% | 4b 6% | Y6: 247 | Z6: TIER 2 CORE KT | AA6: =+IFERROR(VALUE(RIGHT(Tabla5[[#This Row],[B2B]],6)),"") -> 247 | AB6: =+IFERROR(VLOOKUP(Z6,Auxiliar!$A:$C,2,0),"") -> CORE | AC6: =+IFERROR(VLOOKUP(Z6,Auxiliar!$A:$C,3,0),"") -> 0b 1% | 3b 4% | 5b 6% | AE6: 601 | AF6: TIER 3 CORE KT | AG6: =+IFERROR(VALUE(RIGHT(Tabla6[[#This Row],[B2B]],6)),"") -> 601 | AH6: =+IFERROR(VLOOKUP(AF6,Auxiliar!$A:$C,2,0),"") -> CORE | AI6: =+IFERROR(VLOOKUP(AF6,Auxiliar!$A:$C,3,0),"") -> 0b 1% | 6b 5% | 10b 6% | AK6: 71 | AL6: LATONES KT 1 | AM6: =+IFERROR(VALUE(RIGHT(Tabla7[[#This Row],[B2B]],6)),"") -> 71 | AN6: =+IFERROR(VLOOKUP(AL6,Auxiliar!$A:$C,2,0),"") -> LATONES | AO6: =+IFERROR(VLOOKUP(AL6,Auxiliar!$A:$C,3,0),"") -> 1b 4% | 5b 7% | 97b 0% | AQ6: 197 | AR6: LATONES KT 2 | AS6: =+IFERROR(VALUE(RIGHT(Tabla8[[#This Row],[B2B]],6)),"") -> 197 | AT6: =+IFERROR(VLOOKUP(AR6,Auxiliar!$A:$C,2,0),"") -> LATONES | AU6: =+IFERROR(VLOOKUP(AR6,Auxiliar!$A:$C,3,0),"") -> 2b 3% | 4b 5% | 5b 8% | 193 0% | AW6: 3018 | AX6: LATONES AS 1 | AY6: =+IFERROR(VALUE(RIGHT(Tabla9[[#This Row],[B2B]],6)),"") -> 3018 | AZ6: =+IFERROR(VLOOKUP(AX6,Auxiliar!$A:$C,2,0),"") -> LATONES | BA6: =+IFERROR(VLOOKUP(AX6,Auxiliar!$A:$C,3,0),"") -> 2b 3% | 4b 4% | 6b 5% | 10b 8% | 385b 0% | BC6: 1962 | BD6: LATONES AS 2 | BE6: =+IFERROR(VALUE(RIGHT(Tabla10[[#This Row],[B2B]],6)),"") -> 1962 | BF6: =+IFERROR(VLOOKUP(BD6,Auxiliar!$A:$C,2,0),"") -> LATONES | BG6: =+IFERROR(VLOOKUP(BD6,Auxiliar!$A:$C,3,0),"") -> 6b 4% | 12b 5% | 15b 8% | 385b 0% | BI6: 4328 | BJ6: 1890 LITRO AS | BK6: =+IFERROR(VALUE(RIGHT(Tabla11[[#This Row],[B2B]],6)),"") -> 4328 | BL6: =+IFERROR(VLOOKUP(BJ6,Auxiliar!$A:$C,2,0),"") -> VALUE LITRO | BM6: =+IFERROR(VLOOKUP(BJ6,Auxiliar!$A:$C,3,0),"") -> 3b 12% | BO6: 3867 | BP6: 1890 LITRO KT | BQ6: =+IFERROR(VALUE(RIGHT(Tabla12[[#This Row],[B2B]],6)),"") -> 3867 | BR6: =+IFERROR(VLOOKUP(BP6,Auxiliar!$A:$C,2,0),"") -> VALUE LITRO | BS6: =+IFERROR(VLOOKUP(BP6,Auxiliar!$A:$C,3,0),"") -> 1b 12% | BU6: 1226 | BV6: CORONA 710 AS | BW6: =+IFERROR(VALUE(RIGHT(Tabla13[[#This Row],[B2B]],6)),"") -> 1226 | BX6: =+IFERROR(VLOOKUP(BV6,Auxiliar!$A:$C,2,0),"") -> Corona 710cc | BY6: =+IFERROR(VLOOKUP(BV6,Auxiliar!$A:$C,3,0),"") -> 3b 10% | 169b 0% | CA6: 45 | CB6: CORONA 710 KT | CC6: =+IFERROR(VALUE(RIGHT(Tabla14[[#This Row],[B2B]],6)),"") -> 45 | CD6: =+IFERROR(VLOOKUP(CB6,Auxiliar!$A:$C,2,0),"") -> Corona 710cc | CE6: =+IFERROR(VLOOKUP(CB6,Auxiliar!$A:$C,3,0),"") -> 1b 10% | 85b 0% | CG6: 4328 | CH6: 1890 LATA AS | CI6: =+IFERROR(VALUE(RIGHT(Tabla15[[#This Row],[B2B]],6)),"") -> 4328 | CJ6: =+IFERROR(VLOOKUP(CH6,Auxiliar!$A:$C,2,0),"") -> VALUE LATA | CK6: =+IFERROR(VLOOKUP(CH6,Auxiliar!$A:$C,3,0),"") -> 3b 15% | 100b 18% | CM6: 45 | CN6: SIN ALCOHOL | CO6: 45 | CP6: SIN ALCOHOL | CQ6: 0b 0% | CS6: 1226 | CT6: AO, PAT y SA - AS | CU6: =+IFERROR(VALUE(RIGHT(Tabla17[[#This Row],[B2B]],6)),"") -> 1226 | CV6: =+IFERROR(VLOOKUP(CT6,Auxiliar!$A:$C,2,0),"") -> PREMIUM | CW6: =+IFERROR(VLOOKUP(CT6,Auxiliar!$A:$C,3,0),"") -> 0b 0% | 5b 2% | 10b 3,5% | 20b 5% | CY6: 45 | CZ6: AO, PAT y SA - K+T | DA6: =+IFERROR(VALUE(RIGHT(Tabla18[[#This Row],[B2B]],6)),"") -> 45 | DB6: =+IFERROR(VLOOKUP(CZ6,Auxiliar!$A:$C,2,0),"") -> PREMIUM | DC6: =+IFERROR(VLOOKUP(CZ6,Auxiliar!$A:$C,3,0),"") -> 0b 0% | 2b 2% | 5b 3,5% | 10b 5% | DE6: 45 | DF6: MICHELOB | DG6: =+IFERROR(VALUE(RIGHT(Tabla19[[#This Row],[B2B]],6)),"") -> 45 | DH6: =+IFERROR(VLOOKUP(DF6,Auxiliar!$A:$C,2,0),"") -> MICHELOB | DI6: =+IFERROR(VLOOKUP(DF6,Auxiliar!$A:$C,3,0),"") -> 1b 7% | 3b 22% | 8b 27% | DK6: 1226 | DL6: CORONA PORRON AS | DM6: =+IFERROR(VALUE(RIGHT(Tabla20[[#This Row],[B2B]],6)),"") -> 1226 | DN6: =+IFERROR(VLOOKUP(DL6,Auxiliar!$A:$C,2,0),"") -> CORONA PORRON | DO6: =+IFERROR(VLOOKUP(DL6,Auxiliar!$A:$C,3,0),"") -> 3b 5% | 42b 0% | DQ6: 45 | DR6: CORONA PORRON KT | DS6: =+IFERROR(VALUE(RIGHT(Tabla21[[#This Row],[B2B]],6)),"") -> 45 | DT6: =+IFERROR(VLOOKUP(DR6,Auxiliar!$A:$C,2,0),"") -> CORONA PORRON | DU6: =+IFERROR(VLOOKUP(DR6,Auxiliar!$A:$C,3,0),"") -> 1b 5% | 20b 0% | DW6: 3867 | DX6: 1890 LATA KT | DY6: =+IFERROR(VALUE(RIGHT(Tabla22[[#This Row],[B2B]],6)),"") -> 3867 | DZ6: =+IFERROR(VLOOKUP(DX6,Auxiliar!$A:$C,2,0),"") -> VALUE LATA | EA6: =+IFERROR(VLOOKUP(DX6,Auxiliar!$A:$C,3,0),"") -> 1b 15% | 100b 18% | EC6: 3867 | ED6: 1890 LATON | EE6: =+IFERROR(VALUE(RIGHT(Tabla23[[#This Row],[B2B]],6)),"") -> 3867 | EF6: =+IFERROR(VLOOKUP(ED6,Auxiliar!$A:$C,2,0),"") -> VALUE LATON | EG6: =+IFERROR(VLOOKUP(ED6,Auxiliar!$A:$C,3,0),"") -> 1b 10% | 5b 15% | 192b 0% | EI6: 4373 | EJ6: 1890 LATON AS | EK6: =+IFERROR(VALUE(RIGHT(Tabla24[[#This Row],[B2B]],6)),"") -> 4373 | EL6: =+IFERROR(VLOOKUP(EJ6,Auxiliar!$A:$C,2,0),"") -> VALUE LATON | EM6: =+IFERROR(VLOOKUP(EJ6,Auxiliar!$A:$C,3,0),"") -> 3b 10% | 10b 15% | 384b 0% | EQ6: =+IFERROR(VALUE(RIGHT(Tabla25[[#This Row],[B2B]],6)),"") | ER6: =+IFERROR(VLOOKUP(EP6,Auxiliar!$A:$C,2,0),"") | ES6: =+IFERROR(VLOOKUP(EP6,Auxiliar!$A:$C,3,0),"") | EW6: =+IFERROR(VALUE(RIGHT(Tabla26[[#This Row],[B2B]],6)),"") | EX6: =+IFERROR(VLOOKUP(EV6,Auxiliar!$A:$C,2,0),"") | EY6: =+IFERROR(VLOOKUP(EV6,Auxiliar!$A:$C,3,0),"") | EZ6: 2070 | FA6: LLENADO KT 3 | FB6: =+IFERROR(VALUE(RIGHT(Tabla27[[#This Row],[B2B]],6)),"") -> 2070 | FC6: =+IFERROR(VLOOKUP(FA6,Auxiliar!$A:$C,2,0),"") -> CORE 2 | FD6: =+IFERROR(VLOOKUP(FA6,Auxiliar!$A:$C,3,0),"") -> 25b 9% | FG6: =+IFERROR(VALUE(RIGHT(Tabla28[[#This Row],[B2B]],6)),"") | FH6: =+IFERROR(VLOOKUP(FF6,Auxiliar!$A:$C,2,0),"") | FI6: =+IFERROR(VLOOKUP(FF6,Auxiliar!$A:$C,3,0),"") | FL6: =+IFERROR(VALUE(RIGHT(Tabla29[[#This Row],[B2B]],6)),"") | FM6: =+IFERROR(VLOOKUP(FK6,Auxiliar!$A:$C,2,0),"") | FN6: =+IFERROR(VLOOKUP(FK6,Auxiliar!$A:$C,3,0),"") | FQ6: =+IFERROR(VALUE(RIGHT(Tabla30[[#This Row],[B2B]],6)),"") | FR6: =+IFERROR(VLOOKUP(FP6,Auxiliar!$A:$C,2,0),"") | FV6: =+IFERROR(VALUE(RIGHT(Tabla31[[#This Row],[B2B]],6)),"") | FW6: =+IFERROR(VLOOKUP(FU6,Auxiliar!$A:$C,2,0),"") | FX6: =+IFERROR(VLOOKUP(FU6,Auxiliar!$A:$C,3,0),"") | GA6: =+IFERROR(VALUE(RIGHT(Tabla32[[#This Row],[B2B]],6)),"") | GB6: =+IFERROR(VLOOKUP(FZ6,Auxiliar!$A:$C,2,0),"") | GC6: =+IFERROR(VLOOKUP(FZ6,Auxiliar!$A:$C,3,0),"") | GF6: =+IFERROR(VALUE(RIGHT(Tabla33[[#This Row],[B2B]],6)),"") | GG6: =+IFERROR(VLOOKUP(GE6,Auxiliar!$A:$C,2,0),"") | GH6: =+IFERROR(VLOOKUP(GE6,Auxiliar!$A:$C,3,0),"")
A7: 2822 | B7: TIER 1 CORE AS | C7: =+IFERROR(VALUE(RIGHT(Tabla1[[#This Row],[B2B]],6)),"") -> 2822 | D7: =+IFERROR(VLOOKUP(B7,Auxiliar!$A:$C,2,0),"") -> CORE | E7: =+IFERROR(VLOOKUP(B7,Auxiliar!$A:$C,3,0),"") -> 0b 1% | 5b 4% | 10b 5% | 15b 6% | 25b 9% | G7: 4057 | H7: TIER 2 CORE AS | I7: =+IFERROR(VALUE(RIGHT(Tabla2[[#This Row],[B2B]],6)),"") -> 4057 | J7: =+IFERROR(VLOOKUP(H7,Auxiliar!$A:$C,2,0),"") -> CORE | K7: =+IFERROR(VLOOKUP(H7,Auxiliar!$A:$C,3,0),"") -> 0b 1% | 15b 4% | 40b 5% | 60b 9% | O7: =+IFERROR(VALUE(RIGHT(Tabla3[[#This Row],[B2B]],6)),"") | P7: =+IFERROR(VLOOKUP(N7,Auxiliar!$A:$C,2,0),"") | Q7: =+IFERROR(VLOOKUP(N7,Auxiliar!$A:$C,3,0),"") | S7: 96 | T7: TIER 1 CORE KT | U7: =+IFERROR(VALUE(RIGHT(Tabla4[[#This Row],[B2B]],6)),"") -> 96 | V7: =+IFERROR(VLOOKUP(T7,Auxiliar!$A:$C,2,0),"") -> CORE | W7: =+IFERROR(VLOOKUP(T7,Auxiliar!$A:$C,3,0),"") -> 0b 1% | 2b 5% | 4b 6% | Y7: 493 | Z7: TIER 2 CORE KT | AA7: =+IFERROR(VALUE(RIGHT(Tabla5[[#This Row],[B2B]],6)),"") -> 493 | AB7: =+IFERROR(VLOOKUP(Z7,Auxiliar!$A:$C,2,0),"") -> CORE | AC7: =+IFERROR(VLOOKUP(Z7,Auxiliar!$A:$C,3,0),"") -> 0b 1% | 3b 4% | 5b 6% | AE7: 630 | AF7: TIER 3 CORE KT | AG7: =+IFERROR(VALUE(RIGHT(Tabla6[[#This Row],[B2B]],6)),"") -> 630 | AH7: =+IFERROR(VLOOKUP(AF7,Auxiliar!$A:$C,2,0),"") -> CORE | AI7: =+IFERROR(VLOOKUP(AF7,Auxiliar!$A:$C,3,0),"") -> 0b 1% | 6b 5% | 10b 6% | AK7: 72 | AL7: LATONES KT 1 | AM7: =+IFERROR(VALUE(RIGHT(Tabla7[[#This Row],[B2B]],6)),"") -> 72 | AN7: =+IFERROR(VLOOKUP(AL7,Auxiliar!$A:$C,2,0),"") -> LATONES | AO7: =+IFERROR(VLOOKUP(AL7,Auxiliar!$A:$C,3,0),"") -> 1b 4% | 5b 7% | 97b 0% | AQ7: 311 | AR7: LATONES KT 2 | AS7: =+IFERROR(VALUE(RIGHT(Tabla8[[#This Row],[B2B]],6)),"") -> 311 | AT7: =+IFERROR(VLOOKUP(AR7,Auxiliar!$A:$C,2,0),"") -> LATONES | AU7: =+IFERROR(VLOOKUP(AR7,Auxiliar!$A:$C,3,0),"") -> 2b 3% | 4b 5% | 5b 8% | 193 0% | AW7: 3114 | AX7: LATONES AS 1 | AY7: =+IFERROR(VALUE(RIGHT(Tabla9[[#This Row],[B2B]],6)),"") -> 3114 | AZ7: =+IFERROR(VLOOKUP(AX7,Auxiliar!$A:$C,2,0),"") -> LATONES | BA7: =+IFERROR(VLOOKUP(AX7,Auxiliar!$A:$C,3,0),"") -> 2b 3% | 4b 4% | 6b 5% | 10b 8% | 385b 0% | BC7: 2451 | BD7: LATONES AS 2 | BE7: =+IFERROR(VALUE(RIGHT(Tabla10[[#This Row],[B2B]],6)),"") -> 2451 | BF7: =+IFERROR(VLOOKUP(BD7,Auxiliar!$A:$C,2,0),"") -> LATONES | BG7: =+IFERROR(VLOOKUP(BD7,Auxiliar!$A:$C,3,0),"") -> 6b 4% | 12b 5% | 15b 8% | 385b 0% | BI7: 4373 | BJ7: 1890 LITRO AS | BK7: =+IFERROR(VALUE(RIGHT(Tabla11[[#This Row],[B2B]],6)),"") -> 4373 | BL7: =+IFERROR(VLOOKUP(BJ7,Auxiliar!$A:$C,2,0),"") -> VALUE LITRO | BM7: =+IFERROR(VLOOKUP(BJ7,Auxiliar!$A:$C,3,0),"") -> 3b 12% | BO7: 3872 | BP7: 1890 LITRO KT | BQ7: =+IFERROR(VALUE(RIGHT(Tabla12[[#This Row],[B2B]],6)),"") -> 3872 | BR7: =+IFERROR(VLOOKUP(BP7,Auxiliar!$A:$C,2,0),"") -> VALUE LITRO | BS7: =+IFERROR(VLOOKUP(BP7,Auxiliar!$A:$C,3,0),"") -> 1b 12% | BU7: 1962 | BV7: CORONA 710 AS | BW7: =+IFERROR(VALUE(RIGHT(Tabla13[[#This Row],[B2B]],6)),"") -> 1962 | BX7: =+IFERROR(VLOOKUP(BV7,Auxiliar!$A:$C,2,0),"") -> Corona 710cc | BY7: =+IFERROR(VLOOKUP(BV7,Auxiliar!$A:$C,3,0),"") -> 3b 10% | 169b 0% | CA7: 55 | CB7: CORONA 710 KT | CC7: =+IFERROR(VALUE(RIGHT(Tabla14[[#This Row],[B2B]],6)),"") -> 55 | CD7: =+IFERROR(VLOOKUP(CB7,Auxiliar!$A:$C,2,0),"") -> Corona 710cc | CE7: =+IFERROR(VLOOKUP(CB7,Auxiliar!$A:$C,3,0),"") -> 1b 10% | 85b 0% | CG7: 4373 | CH7: 1890 LATA AS | CI7: =+IFERROR(VALUE(RIGHT(Tabla15[[#This Row],[B2B]],6)),"") -> 4373 | CJ7: =+IFERROR(VLOOKUP(CH7,Auxiliar!$A:$C,2,0),"") -> VALUE LATA | CK7: =+IFERROR(VLOOKUP(CH7,Auxiliar!$A:$C,3,0),"") -> 3b 15% | 100b 18% | CM7: 55 | CN7: SIN ALCOHOL | CO7: 55 | CP7: SIN ALCOHOL | CQ7: 0b 0% | CS7: 1962 | CT7: AO, PAT y SA - AS | CU7: =+IFERROR(VALUE(RIGHT(Tabla17[[#This Row],[B2B]],6)),"") -> 1962 | CV7: =+IFERROR(VLOOKUP(CT7,Auxiliar!$A:$C,2,0),"") -> PREMIUM | CW7: =+IFERROR(VLOOKUP(CT7,Auxiliar!$A:$C,3,0),"") -> 0b 0% | 5b 2% | 10b 3,5% | 20b 5% | CY7: 55 | CZ7: AO, PAT y SA - K+T | DA7: =+IFERROR(VALUE(RIGHT(Tabla18[[#This Row],[B2B]],6)),"") -> 55 | DB7: =+IFERROR(VLOOKUP(CZ7,Auxiliar!$A:$C,2,0),"") -> PREMIUM | DC7: =+IFERROR(VLOOKUP(CZ7,Auxiliar!$A:$C,3,0),"") -> 0b 0% | 2b 2% | 5b 3,5% | 10b 5% | DE7: 55 | DF7: MICHELOB | DG7: =+IFERROR(VALUE(RIGHT(Tabla19[[#This Row],[B2B]],6)),"") -> 55 | DH7: =+IFERROR(VLOOKUP(DF7,Auxiliar!$A:$C,2,0),"") -> MICHELOB | DI7: =+IFERROR(VLOOKUP(DF7,Auxiliar!$A:$C,3,0),"") -> 1b 7% | 3b 22% | 8b 27% | DK7: 1962 | DL7: CORONA PORRON AS | DM7: =+IFERROR(VALUE(RIGHT(Tabla20[[#This Row],[B2B]],6)),"") -> 1962 | DN7: =+IFERROR(VLOOKUP(DL7,Auxiliar!$A:$C,2,0),"") -> CORONA PORRON | DO7: =+IFERROR(VLOOKUP(DL7,Auxiliar!$A:$C,3,0),"") -> 3b 5% | 42b 0% | DQ7: 55 | DR7: CORONA PORRON KT | DS7: =+IFERROR(VALUE(RIGHT(Tabla21[[#This Row],[B2B]],6)),"") -> 55 | DT7: =+IFERROR(VLOOKUP(DR7,Auxiliar!$A:$C,2,0),"") -> CORONA PORRON | DU7: =+IFERROR(VLOOKUP(DR7,Auxiliar!$A:$C,3,0),"") -> 1b 5% | 20b 0% | DW7: 3872 | DX7: 1890 LATA KT | DY7: =+IFERROR(VALUE(RIGHT(Tabla22[[#This Row],[B2B]],6)),"") -> 3872 | DZ7: =+IFERROR(VLOOKUP(DX7,Auxiliar!$A:$C,2,0),"") -> VALUE LATA | EA7: =+IFERROR(VLOOKUP(DX7,Auxiliar!$A:$C,3,0),"") -> 1b 15% | 100b 18% | EC7: 3872 | ED7: 1890 LATON | EE7: =+IFERROR(VALUE(RIGHT(Tabla23[[#This Row],[B2B]],6)),"") -> 3872 | EF7: =+IFERROR(VLOOKUP(ED7,Auxiliar!$A:$C,2,0),"") -> VALUE LATON | EG7: =+IFERROR(VLOOKUP(ED7,Auxiliar!$A:$C,3,0),"") -> 1b 10% | 5b 15% | 192b 0% | EI7: 4400 | EJ7: 1890 LATON AS | EK7: =+IFERROR(VALUE(RIGHT(Tabla24[[#This Row],[B2B]],6)),"") -> 4400 | EL7: =+IFERROR(VLOOKUP(EJ7,Auxiliar!$A:$C,2,0),"") -> VALUE LATON | EM7: =+IFERROR(VLOOKUP(EJ7,Auxiliar!$A:$C,3,0),"") -> 3b 10% | 10b 15% | 384b 0% | EQ7: =+IFERROR(VALUE(RIGHT(Tabla25[[#This Row],[B2B]],6)),"") | ER7: =+IFERROR(VLOOKUP(EP7,Auxiliar!$A:$C,2,0),"") | ES7: =+IFERROR(VLOOKUP(EP7,Auxiliar!$A:$C,3,0),"") | EW7: =+IFERROR(VALUE(RIGHT(Tabla26[[#This Row],[B2B]],6)),"") | EX7: =+IFERROR(VLOOKUP(EV7,Auxiliar!$A:$C,2,0),"") | EY7: =+IFERROR(VLOOKUP(EV7,Auxiliar!$A:$C,3,0),"") | EZ7: 2380 | FA7: LLENADO KT 3 | FB7: =+IFERROR(VALUE(RIGHT(Tabla27[[#This Row],[B2B]],6)),"") -> 2380 | FC7: =+IFERROR(VLOOKUP(FA7,Auxiliar!$A:$C,2,0),"") -> CORE 2 | FD7: =+IFERROR(VLOOKUP(FA7,Auxiliar!$A:$C,3,0),"") -> 25b 9% | FG7: =+IFERROR(VALUE(RIGHT(Tabla28[[#This Row],[B2B]],6)),"") | FH7: =+IFERROR(VLOOKUP(FF7,Auxiliar!$A:$C,2,0),"") | FI7: =+IFERROR(VLOOKUP(FF7,Auxiliar!$A:$C,3,0),"") | FL7: =+IFERROR(VALUE(RIGHT(Tabla29[[#This Row],[B2B]],6)),"") | FM7: =+IFERROR(VLOOKUP(FK7,Auxiliar!$A:$C,2,0),"") | FN7: =+IFERROR(VLOOKUP(FK7,Auxiliar!$A:$C,3,0),"") | FQ7: =+IFERROR(VALUE(RIGHT(Tabla30[[#This Row],[B2B]],6)),"") | FR7: =+IFERROR(VLOOKUP(FP7,Auxiliar!$A:$C,2,0),"") | FV7: =+IFERROR(VALUE(RIGHT(Tabla31[[#This Row],[B2B]],6)),"") | FW7: =+IFERROR(VLOOKUP(FU7,Auxiliar!$A:$C,2,0),"") | FX7: =+IFERROR(VLOOKUP(FU7,Auxiliar!$A:$C,3,0),"") | GA7: =+IFERROR(VALUE(RIGHT(Tabla32[[#This Row],[B2B]],6)),"") | GB7: =+IFERROR(VLOOKUP(FZ7,Auxiliar!$A:$C,2,0),"") | GC7: =+IFERROR(VLOOKUP(FZ7,Auxiliar!$A:$C,3,0),"") | GF7: =+IFERROR(VALUE(RIGHT(Tabla33[[#This Row],[B2B]],6)),"") | GG7: =+IFERROR(VLOOKUP(GE7,Auxiliar!$A:$C,2,0),"") | GH7: =+IFERROR(VLOOKUP(GE7,Auxiliar!$A:$C,3,0),"")
